[2015/07/15 15:35:14]CRITICAL - horesase_bot.py:134: user_timeline fetch error
Traceback (most recent call last):
  File "horesase_bot.py", line 132, in get_user_text
    user_tweets = api.user_timeline(id=user, count=25)
  File "/usr/local/lib/python3.4/site-packages/tweepy/binder.py", line 239, in _call
    return method.execute()
  File "/usr/local/lib/python3.4/site-packages/tweepy/binder.py", line 223, in execute
    raise TweepError(error_msg, resp)
tweepy.error.TweepError: Twitter error response: status code = 429
[2015/07/15 15:36:04]CRITICAL - horesase_bot.py:134: user_timeline fetch error
Traceback (most recent call last):
  File "horesase_bot.py", line 132, in get_user_text
    user_tweets = api.user_timeline(id=user, count=25)
  File "/usr/local/lib/python3.4/site-packages/tweepy/binder.py", line 239, in _call
    return method.execute()
  File "/usr/local/lib/python3.4/site-packages/tweepy/binder.py", line 223, in execute
    raise TweepError(error_msg, resp)
tweepy.error.TweepError: Twitter error response: status code = 429
[2015/07/15 15:49:16]CRITICAL - horesase_bot.py:134: user_timeline fetch error
Traceback (most recent call last):
  File "horesase_bot.py", line 132, in get_user_text
    user_tweets = api.user_timeline(id=user, count=25)
  File "/usr/local/lib/python3.4/site-packages/tweepy/binder.py", line 239, in _call
    return method.execute()
  File "/usr/local/lib/python3.4/site-packages/tweepy/binder.py", line 223, in execute
    raise TweepError(error_msg, resp)
tweepy.error.TweepError: Twitter error response: status code = 429
[2015/07/15 15:50:04]CRITICAL - horesase_bot.py:134: user_timeline fetch error
Traceback (most recent call last):
  File "horesase_bot.py", line 132, in get_user_text
    user_tweets = api.user_timeline(id=user, count=25)
  File "/usr/local/lib/python3.4/site-packages/tweepy/binder.py", line 239, in _call
    return method.execute()
  File "/usr/local/lib/python3.4/site-packages/tweepy/binder.py", line 223, in execute
    raise TweepError(error_msg, resp)
tweepy.error.TweepError: Twitter error response: status code = 429
[2015/07/15 15:51:03]CRITICAL - horesase_bot.py:134: user_timeline fetch error
Traceback (most recent call last):
  File "horesase_bot.py", line 132, in get_user_text
    user_tweets = api.user_timeline(id=user, count=25)
  File "/usr/local/lib/python3.4/site-packages/tweepy/binder.py", line 239, in _call
    return method.execute()
  File "/usr/local/lib/python3.4/site-packages/tweepy/binder.py", line 223, in execute
    raise TweepError(error_msg, resp)
tweepy.error.TweepError: Twitter error response: status code = 429
[2015/07/15 15:52:01]ERROR - horesase_bot.py:119: failed to get followers/friends
Traceback (most recent call last):
  File "horesase_bot.py", line 112, in api_get_followers
    for friend in c.items():
  File "/usr/local/lib/python3.4/site-packages/tweepy/cursor.py", line 49, in __next__
    return self.next()
  File "/usr/local/lib/python3.4/site-packages/tweepy/cursor.py", line 197, in next
    self.current_page = self.page_iterator.next()
  File "/usr/local/lib/python3.4/site-packages/tweepy/cursor.py", line 75, in next
    **self.kargs)
  File "/usr/local/lib/python3.4/site-packages/tweepy/binder.py", line 239, in _call
    return method.execute()
  File "/usr/local/lib/python3.4/site-packages/tweepy/binder.py", line 223, in execute
    raise TweepError(error_msg, resp)
tweepy.error.TweepError: Twitter error response: status code = 429
[2015/07/15 18:12:16]CRITICAL - horesase_bot.py:134: user_timeline fetch error
Traceback (most recent call last):
  File "horesase_bot.py", line 132, in get_user_text
    user_tweets = api.user_timeline(id=user, count=25)
  File "/usr/local/lib/python3.4/site-packages/tweepy/binder.py", line 239, in _call
    return method.execute()
  File "/usr/local/lib/python3.4/site-packages/tweepy/binder.py", line 223, in execute
    raise TweepError(error_msg, resp)
tweepy.error.TweepError: Twitter error response: status code = 429
[2015/07/15 18:13:03]CRITICAL - horesase_bot.py:134: user_timeline fetch error
Traceback (most recent call last):
  File "horesase_bot.py", line 132, in get_user_text
    user_tweets = api.user_timeline(id=user, count=25)
  File "/usr/local/lib/python3.4/site-packages/tweepy/binder.py", line 239, in _call
    return method.execute()
  File "/usr/local/lib/python3.4/site-packages/tweepy/binder.py", line 223, in execute
    raise TweepError(error_msg, resp)
tweepy.error.TweepError: Twitter error response: status code = 429
[2015/07/15 18:14:03]CRITICAL - horesase_bot.py:134: user_timeline fetch error
Traceback (most recent call last):
  File "horesase_bot.py", line 132, in get_user_text
    user_tweets = api.user_timeline(id=user, count=25)
  File "/usr/local/lib/python3.4/site-packages/tweepy/binder.py", line 239, in _call
    return method.execute()
  File "/usr/local/lib/python3.4/site-packages/tweepy/binder.py", line 223, in execute
    raise TweepError(error_msg, resp)
tweepy.error.TweepError: Twitter error response: status code = 429
[2015/07/15 18:27:14]CRITICAL - horesase_bot.py:134: user_timeline fetch error
Traceback (most recent call last):
  File "horesase_bot.py", line 132, in get_user_text
    user_tweets = api.user_timeline(id=user, count=25)
  File "/usr/local/lib/python3.4/site-packages/tweepy/binder.py", line 239, in _call
    return method.execute()
  File "/usr/local/lib/python3.4/site-packages/tweepy/binder.py", line 223, in execute
    raise TweepError(error_msg, resp)
tweepy.error.TweepError: Twitter error response: status code = 429
[2015/07/15 18:28:04]CRITICAL - horesase_bot.py:134: user_timeline fetch error
Traceback (most recent call last):
  File "horesase_bot.py", line 132, in get_user_text
    user_tweets = api.user_timeline(id=user, count=25)
  File "/usr/local/lib/python3.4/site-packages/tweepy/binder.py", line 239, in _call
    return method.execute()
  File "/usr/local/lib/python3.4/site-packages/tweepy/binder.py", line 223, in execute
    raise TweepError(error_msg, resp)
tweepy.error.TweepError: Twitter error response: status code = 429
[2015/07/15 18:29:03]CRITICAL - horesase_bot.py:134: user_timeline fetch error
Traceback (most recent call last):
  File "horesase_bot.py", line 132, in get_user_text
    user_tweets = api.user_timeline(id=user, count=25)
  File "/usr/local/lib/python3.4/site-packages/tweepy/binder.py", line 239, in _call
    return method.execute()
  File "/usr/local/lib/python3.4/site-packages/tweepy/binder.py", line 223, in execute
    raise TweepError(error_msg, resp)
tweepy.error.TweepError: Twitter error response: status code = 429
[2015/07/15 18:30:04]CRITICAL - horesase_bot.py:134: user_timeline fetch error
Traceback (most recent call last):
  File "horesase_bot.py", line 132, in get_user_text
    user_tweets = api.user_timeline(id=user, count=25)
  File "/usr/local/lib/python3.4/site-packages/tweepy/binder.py", line 239, in _call
    return method.execute()
  File "/usr/local/lib/python3.4/site-packages/tweepy/binder.py", line 223, in execute
    raise TweepError(error_msg, resp)
tweepy.error.TweepError: Twitter error response: status code = 429
[2015/07/15 18:43:15]CRITICAL - horesase_bot.py:134: user_timeline fetch error
Traceback (most recent call last):
  File "horesase_bot.py", line 132, in get_user_text
    user_tweets = api.user_timeline(id=user, count=25)
  File "/usr/local/lib/python3.4/site-packages/tweepy/binder.py", line 239, in _call
    return method.execute()
  File "/usr/local/lib/python3.4/site-packages/tweepy/binder.py", line 223, in execute
    raise TweepError(error_msg, resp)
tweepy.error.TweepError: Twitter error response: status code = 429
[2015/07/15 18:44:04]CRITICAL - horesase_bot.py:134: user_timeline fetch error
Traceback (most recent call last):
  File "horesase_bot.py", line 132, in get_user_text
    user_tweets = api.user_timeline(id=user, count=25)
  File "/usr/local/lib/python3.4/site-packages/tweepy/binder.py", line 239, in _call
    return method.execute()
  File "/usr/local/lib/python3.4/site-packages/tweepy/binder.py", line 223, in execute
    raise TweepError(error_msg, resp)
tweepy.error.TweepError: Twitter error response: status code = 429
[2015/07/15 18:45:02]ERROR - horesase_bot.py:119: failed to get followers/friends
Traceback (most recent call last):
  File "horesase_bot.py", line 116, in api_get_followers
    for friend in c.items():
  File "/usr/local/lib/python3.4/site-packages/tweepy/cursor.py", line 49, in __next__
    return self.next()
  File "/usr/local/lib/python3.4/site-packages/tweepy/cursor.py", line 197, in next
    self.current_page = self.page_iterator.next()
  File "/usr/local/lib/python3.4/site-packages/tweepy/cursor.py", line 75, in next
    **self.kargs)
  File "/usr/local/lib/python3.4/site-packages/tweepy/binder.py", line 239, in _call
    return method.execute()
  File "/usr/local/lib/python3.4/site-packages/tweepy/binder.py", line 223, in execute
    raise TweepError(error_msg, resp)
tweepy.error.TweepError: Twitter error response: status code = 429
[2015/07/15 18:45:03]CRITICAL - horesase_bot.py:134: user_timeline fetch error
Traceback (most recent call last):
  File "horesase_bot.py", line 132, in get_user_text
    user_tweets = api.user_timeline(id=user, count=25)
  File "/usr/local/lib/python3.4/site-packages/tweepy/binder.py", line 239, in _call
    return method.execute()
  File "/usr/local/lib/python3.4/site-packages/tweepy/binder.py", line 223, in execute
    raise TweepError(error_msg, resp)
tweepy.error.TweepError: Twitter error response: status code = 429
[2015/07/15 18:58:15]CRITICAL - horesase_bot.py:134: user_timeline fetch error
Traceback (most recent call last):
  File "horesase_bot.py", line 132, in get_user_text
    user_tweets = api.user_timeline(id=user, count=25)
  File "/usr/local/lib/python3.4/site-packages/tweepy/binder.py", line 239, in _call
    return method.execute()
  File "/usr/local/lib/python3.4/site-packages/tweepy/binder.py", line 223, in execute
    raise TweepError(error_msg, resp)
tweepy.error.TweepError: Twitter error response: status code = 429
[2015/07/15 18:59:04]CRITICAL - horesase_bot.py:134: user_timeline fetch error
Traceback (most recent call last):
  File "horesase_bot.py", line 132, in get_user_text
    user_tweets = api.user_timeline(id=user, count=25)
  File "/usr/local/lib/python3.4/site-packages/tweepy/binder.py", line 239, in _call
    return method.execute()
  File "/usr/local/lib/python3.4/site-packages/tweepy/binder.py", line 223, in execute
    raise TweepError(error_msg, resp)
tweepy.error.TweepError: Twitter error response: status code = 429
[2015/07/15 21:12:15]CRITICAL - horesase_bot.py:134: user_timeline fetch error
Traceback (most recent call last):
  File "horesase_bot.py", line 132, in get_user_text
    user_tweets = api.user_timeline(id=user, count=25)
  File "/usr/local/lib/python3.4/site-packages/tweepy/binder.py", line 239, in _call
    return method.execute()
  File "/usr/local/lib/python3.4/site-packages/tweepy/binder.py", line 223, in execute
    raise TweepError(error_msg, resp)
tweepy.error.TweepError: Twitter error response: status code = 429
[2015/07/15 21:13:04]CRITICAL - horesase_bot.py:134: user_timeline fetch error
Traceback (most recent call last):
  File "horesase_bot.py", line 132, in get_user_text
    user_tweets = api.user_timeline(id=user, count=25)
  File "/usr/local/lib/python3.4/site-packages/tweepy/binder.py", line 239, in _call
    return method.execute()
  File "/usr/local/lib/python3.4/site-packages/tweepy/binder.py", line 223, in execute
    raise TweepError(error_msg, resp)
tweepy.error.TweepError: Twitter error response: status code = 429
[2015/07/15 21:14:04]CRITICAL - horesase_bot.py:134: user_timeline fetch error
Traceback (most recent call last):
  File "horesase_bot.py", line 132, in get_user_text
    user_tweets = api.user_timeline(id=user, count=25)
  File "/usr/local/lib/python3.4/site-packages/tweepy/binder.py", line 239, in _call
    return method.execute()
  File "/usr/local/lib/python3.4/site-packages/tweepy/binder.py", line 223, in execute
    raise TweepError(error_msg, resp)
tweepy.error.TweepError: Twitter error response: status code = 429
[2015/07/15 21:15:02]ERROR - horesase_bot.py:119: failed to get followers/friends
Traceback (most recent call last):
  File "horesase_bot.py", line 112, in api_get_followers
    for friend in c.items():
  File "/usr/local/lib/python3.4/site-packages/tweepy/cursor.py", line 49, in __next__
    return self.next()
  File "/usr/local/lib/python3.4/site-packages/tweepy/cursor.py", line 197, in next
    self.current_page = self.page_iterator.next()
  File "/usr/local/lib/python3.4/site-packages/tweepy/cursor.py", line 75, in next
    **self.kargs)
  File "/usr/local/lib/python3.4/site-packages/tweepy/binder.py", line 239, in _call
    return method.execute()
  File "/usr/local/lib/python3.4/site-packages/tweepy/binder.py", line 223, in execute
    raise TweepError(error_msg, resp)
tweepy.error.TweepError: Twitter error response: status code = 429
[2015/07/15 21:28:15]CRITICAL - horesase_bot.py:134: user_timeline fetch error
Traceback (most recent call last):
  File "horesase_bot.py", line 132, in get_user_text
    user_tweets = api.user_timeline(id=user, count=25)
  File "/usr/local/lib/python3.4/site-packages/tweepy/binder.py", line 239, in _call
    return method.execute()
  File "/usr/local/lib/python3.4/site-packages/tweepy/binder.py", line 223, in execute
    raise TweepError(error_msg, resp)
tweepy.error.TweepError: Twitter error response: status code = 429
[2015/07/15 21:29:03]CRITICAL - horesase_bot.py:134: user_timeline fetch error
Traceback (most recent call last):
  File "horesase_bot.py", line 132, in get_user_text
    user_tweets = api.user_timeline(id=user, count=25)
  File "/usr/local/lib/python3.4/site-packages/tweepy/binder.py", line 239, in _call
    return method.execute()
  File "/usr/local/lib/python3.4/site-packages/tweepy/binder.py", line 223, in execute
    raise TweepError(error_msg, resp)
tweepy.error.TweepError: Twitter error response: status code = 429
[2015/07/15 21:30:04]CRITICAL - horesase_bot.py:134: user_timeline fetch error
Traceback (most recent call last):
  File "horesase_bot.py", line 132, in get_user_text
    user_tweets = api.user_timeline(id=user, count=25)
  File "/usr/local/lib/python3.4/site-packages/tweepy/binder.py", line 239, in _call
    return method.execute()
  File "/usr/local/lib/python3.4/site-packages/tweepy/binder.py", line 223, in execute
    raise TweepError(error_msg, resp)
tweepy.error.TweepError: Twitter error response: status code = 429
[2015/07/15 21:31:02]ERROR - horesase_bot.py:119: failed to get followers/friends
Traceback (most recent call last):
  File "horesase_bot.py", line 112, in api_get_followers
    for friend in c.items():
  File "/usr/local/lib/python3.4/site-packages/tweepy/cursor.py", line 49, in __next__
    return self.next()
  File "/usr/local/lib/python3.4/site-packages/tweepy/cursor.py", line 197, in next
    self.current_page = self.page_iterator.next()
  File "/usr/local/lib/python3.4/site-packages/tweepy/cursor.py", line 75, in next
    **self.kargs)
  File "/usr/local/lib/python3.4/site-packages/tweepy/binder.py", line 239, in _call
    return method.execute()
  File "/usr/local/lib/python3.4/site-packages/tweepy/binder.py", line 223, in execute
    raise TweepError(error_msg, resp)
tweepy.error.TweepError: Twitter error response: status code = 429
[2015/07/15 21:44:16]CRITICAL - horesase_bot.py:134: user_timeline fetch error
Traceback (most recent call last):
  File "horesase_bot.py", line 132, in get_user_text
    user_tweets = api.user_timeline(id=user, count=25)
  File "/usr/local/lib/python3.4/site-packages/tweepy/binder.py", line 239, in _call
    return method.execute()
  File "/usr/local/lib/python3.4/site-packages/tweepy/binder.py", line 223, in execute
    raise TweepError(error_msg, resp)
tweepy.error.TweepError: Twitter error response: status code = 429
[2015/07/15 21:45:03]CRITICAL - horesase_bot.py:134: user_timeline fetch error
Traceback (most recent call last):
  File "horesase_bot.py", line 132, in get_user_text
    user_tweets = api.user_timeline(id=user, count=25)
  File "/usr/local/lib/python3.4/site-packages/tweepy/binder.py", line 239, in _call
    return method.execute()
  File "/usr/local/lib/python3.4/site-packages/tweepy/binder.py", line 223, in execute
    raise TweepError(error_msg, resp)
tweepy.error.TweepError: Twitter error response: status code = 429
[2015/07/15 21:46:04]CRITICAL - horesase_bot.py:134: user_timeline fetch error
Traceback (most recent call last):
  File "horesase_bot.py", line 132, in get_user_text
    user_tweets = api.user_timeline(id=user, count=25)
  File "/usr/local/lib/python3.4/site-packages/tweepy/binder.py", line 239, in _call
    return method.execute()
  File "/usr/local/lib/python3.4/site-packages/tweepy/binder.py", line 223, in execute
    raise TweepError(error_msg, resp)
tweepy.error.TweepError: Twitter error response: status code = 429
[2015/07/15 21:47:02]ERROR - horesase_bot.py:119: failed to get followers/friends
Traceback (most recent call last):
  File "horesase_bot.py", line 112, in api_get_followers
    for friend in c.items():
  File "/usr/local/lib/python3.4/site-packages/tweepy/cursor.py", line 49, in __next__
    return self.next()
  File "/usr/local/lib/python3.4/site-packages/tweepy/cursor.py", line 197, in next
    self.current_page = self.page_iterator.next()
  File "/usr/local/lib/python3.4/site-packages/tweepy/cursor.py", line 75, in next
    **self.kargs)
  File "/usr/local/lib/python3.4/site-packages/tweepy/binder.py", line 239, in _call
    return method.execute()
  File "/usr/local/lib/python3.4/site-packages/tweepy/binder.py", line 223, in execute
    raise TweepError(error_msg, resp)
tweepy.error.TweepError: Twitter error response: status code = 429
[2015/07/16 00:12:15]CRITICAL - horesase_bot.py:134: user_timeline fetch error
Traceback (most recent call last):
  File "horesase_bot.py", line 132, in get_user_text
    user_tweets = api.user_timeline(id=user, count=25)
  File "/usr/local/lib/python3.4/site-packages/tweepy/binder.py", line 239, in _call
    return method.execute()
  File "/usr/local/lib/python3.4/site-packages/tweepy/binder.py", line 223, in execute
    raise TweepError(error_msg, resp)
tweepy.error.TweepError: Twitter error response: status code = 429
[2015/07/16 00:13:04]CRITICAL - horesase_bot.py:134: user_timeline fetch error
Traceback (most recent call last):
  File "horesase_bot.py", line 132, in get_user_text
    user_tweets = api.user_timeline(id=user, count=25)
  File "/usr/local/lib/python3.4/site-packages/tweepy/binder.py", line 239, in _call
    return method.execute()
  File "/usr/local/lib/python3.4/site-packages/tweepy/binder.py", line 223, in execute
    raise TweepError(error_msg, resp)
tweepy.error.TweepError: Twitter error response: status code = 429
[2015/07/16 00:14:03]CRITICAL - horesase_bot.py:134: user_timeline fetch error
Traceback (most recent call last):
  File "horesase_bot.py", line 132, in get_user_text
    user_tweets = api.user_timeline(id=user, count=25)
  File "/usr/local/lib/python3.4/site-packages/tweepy/binder.py", line 239, in _call
    return method.execute()
  File "/usr/local/lib/python3.4/site-packages/tweepy/binder.py", line 223, in execute
    raise TweepError(error_msg, resp)
tweepy.error.TweepError: Twitter error response: status code = 429
[2015/07/16 00:15:01]ERROR - horesase_bot.py:119: failed to get followers/friends
Traceback (most recent call last):
  File "horesase_bot.py", line 112, in api_get_followers
    for friend in c.items():
  File "/usr/local/lib/python3.4/site-packages/tweepy/cursor.py", line 49, in __next__
    return self.next()
  File "/usr/local/lib/python3.4/site-packages/tweepy/cursor.py", line 197, in next
    self.current_page = self.page_iterator.next()
  File "/usr/local/lib/python3.4/site-packages/tweepy/cursor.py", line 75, in next
    **self.kargs)
  File "/usr/local/lib/python3.4/site-packages/tweepy/binder.py", line 239, in _call
    return method.execute()
  File "/usr/local/lib/python3.4/site-packages/tweepy/binder.py", line 223, in execute
    raise TweepError(error_msg, resp)
tweepy.error.TweepError: Twitter error response: status code = 429
[2015/07/16 00:28:16]CRITICAL - horesase_bot.py:134: user_timeline fetch error
Traceback (most recent call last):
  File "horesase_bot.py", line 132, in get_user_text
    user_tweets = api.user_timeline(id=user, count=25)
  File "/usr/local/lib/python3.4/site-packages/tweepy/binder.py", line 239, in _call
    return method.execute()
  File "/usr/local/lib/python3.4/site-packages/tweepy/binder.py", line 223, in execute
    raise TweepError(error_msg, resp)
tweepy.error.TweepError: Twitter error response: status code = 429
[2015/07/16 00:29:03]CRITICAL - horesase_bot.py:134: user_timeline fetch error
Traceback (most recent call last):
  File "horesase_bot.py", line 132, in get_user_text
    user_tweets = api.user_timeline(id=user, count=25)
  File "/usr/local/lib/python3.4/site-packages/tweepy/binder.py", line 239, in _call
    return method.execute()
  File "/usr/local/lib/python3.4/site-packages/tweepy/binder.py", line 223, in execute
    raise TweepError(error_msg, resp)
tweepy.error.TweepError: Twitter error response: status code = 429
[2015/07/16 00:30:03]CRITICAL - horesase_bot.py:134: user_timeline fetch error
Traceback (most recent call last):
  File "horesase_bot.py", line 132, in get_user_text
    user_tweets = api.user_timeline(id=user, count=25)
  File "/usr/local/lib/python3.4/site-packages/tweepy/binder.py", line 239, in _call
    return method.execute()
  File "/usr/local/lib/python3.4/site-packages/tweepy/binder.py", line 223, in execute
    raise TweepError(error_msg, resp)
tweepy.error.TweepError: Twitter error response: status code = 429
[2015/07/16 00:43:15]CRITICAL - horesase_bot.py:134: user_timeline fetch error
Traceback (most recent call last):
  File "horesase_bot.py", line 132, in get_user_text
    user_tweets = api.user_timeline(id=user, count=25)
  File "/usr/local/lib/python3.4/site-packages/tweepy/binder.py", line 239, in _call
    return method.execute()
  File "/usr/local/lib/python3.4/site-packages/tweepy/binder.py", line 223, in execute
    raise TweepError(error_msg, resp)
tweepy.error.TweepError: Twitter error response: status code = 429
[2015/07/16 00:44:04]CRITICAL - horesase_bot.py:134: user_timeline fetch error
Traceback (most recent call last):
  File "horesase_bot.py", line 132, in get_user_text
    user_tweets = api.user_timeline(id=user, count=25)
  File "/usr/local/lib/python3.4/site-packages/tweepy/binder.py", line 239, in _call
    return method.execute()
  File "/usr/local/lib/python3.4/site-packages/tweepy/binder.py", line 223, in execute
    raise TweepError(error_msg, resp)
tweepy.error.TweepError: Twitter error response: status code = 429
[2015/07/16 00:45:04]CRITICAL - horesase_bot.py:134: user_timeline fetch error
Traceback (most recent call last):
  File "horesase_bot.py", line 132, in get_user_text
    user_tweets = api.user_timeline(id=user, count=25)
  File "/usr/local/lib/python3.4/site-packages/tweepy/binder.py", line 239, in _call
    return method.execute()
  File "/usr/local/lib/python3.4/site-packages/tweepy/binder.py", line 223, in execute
    raise TweepError(error_msg, resp)
tweepy.error.TweepError: Twitter error response: status code = 429
[2015/07/16 00:46:02]ERROR - horesase_bot.py:119: failed to get followers/friends
Traceback (most recent call last):
  File "horesase_bot.py", line 112, in api_get_followers
    for friend in c.items():
  File "/usr/local/lib/python3.4/site-packages/tweepy/cursor.py", line 49, in __next__
    return self.next()
  File "/usr/local/lib/python3.4/site-packages/tweepy/cursor.py", line 197, in next
    self.current_page = self.page_iterator.next()
  File "/usr/local/lib/python3.4/site-packages/tweepy/cursor.py", line 75, in next
    **self.kargs)
  File "/usr/local/lib/python3.4/site-packages/tweepy/binder.py", line 239, in _call
    return method.execute()
  File "/usr/local/lib/python3.4/site-packages/tweepy/binder.py", line 223, in execute
    raise TweepError(error_msg, resp)
tweepy.error.TweepError: Twitter error response: status code = 429
[2015/07/16 00:59:15]CRITICAL - horesase_bot.py:134: user_timeline fetch error
Traceback (most recent call last):
  File "horesase_bot.py", line 132, in get_user_text
    user_tweets = api.user_timeline(id=user, count=25)
  File "/usr/local/lib/python3.4/site-packages/tweepy/binder.py", line 239, in _call
    return method.execute()
  File "/usr/local/lib/python3.4/site-packages/tweepy/binder.py", line 223, in execute
    raise TweepError(error_msg, resp)
tweepy.error.TweepError: Twitter error response: status code = 429
[2015/07/16 03:00:13]ERROR - horesase_bot.py:229: reply error
Traceback (most recent call last):
  File "horesase_bot.py", line 227, in main
    api.update_with_media('picture.gif', reply_text, in_reply_status_id='user_tweet.id')
  File "/usr/local/lib/python3.4/site-packages/tweepy/api.py", line 231, in update_with_media
    )(*args, **kwargs)
  File "/usr/local/lib/python3.4/site-packages/tweepy/binder.py", line 239, in _call
    return method.execute()
  File "/usr/local/lib/python3.4/site-packages/tweepy/binder.py", line 223, in execute
    raise TweepError(error_msg, resp)
tweepy.error.TweepError: Twitter error response: status code = 403
[2015/07/16 10:00:29]ERROR - horesase_bot.py:229: reply error
Traceback (most recent call last):
  File "horesase_bot.py", line 227, in main
    api.update_with_media('picture.gif', reply_text, in_reply_status_id='user_tweet.id')
  File "/usr/local/lib/python3.4/site-packages/tweepy/api.py", line 231, in update_with_media
    )(*args, **kwargs)
  File "/usr/local/lib/python3.4/site-packages/tweepy/binder.py", line 239, in _call
    return method.execute()
  File "/usr/local/lib/python3.4/site-packages/tweepy/binder.py", line 223, in execute
    raise TweepError(error_msg, resp)
tweepy.error.TweepError: Twitter error response: status code = 403
[2015/07/16 15:37:05]ERROR - horesase_bot.py:229: reply error
Traceback (most recent call last):
  File "horesase_bot.py", line 227, in main
    api.update_with_media('picture.gif', reply_text, in_reply_status_id='user_tweet.id')
  File "/usr/local/lib/python3.4/site-packages/tweepy/api.py", line 231, in update_with_media
    )(*args, **kwargs)
  File "/usr/local/lib/python3.4/site-packages/tweepy/binder.py", line 239, in _call
    return method.execute()
  File "/usr/local/lib/python3.4/site-packages/tweepy/binder.py", line 223, in execute
    raise TweepError(error_msg, resp)
tweepy.error.TweepError: Twitter error response: status code = 403
[2015/07/16 23:00:16]ERROR - horesase_bot.py:229: reply error
Traceback (most recent call last):
  File "horesase_bot.py", line 227, in main
    api.update_with_media('picture.gif', reply_text, in_reply_status_id='user_tweet.id')
  File "/usr/local/lib/python3.4/site-packages/tweepy/api.py", line 231, in update_with_media
    )(*args, **kwargs)
  File "/usr/local/lib/python3.4/site-packages/tweepy/binder.py", line 239, in _call
    return method.execute()
  File "/usr/local/lib/python3.4/site-packages/tweepy/binder.py", line 223, in execute
    raise TweepError(error_msg, resp)
tweepy.error.TweepError: Twitter error response: status code = 403
[2015/07/16 23:00:24]ERROR - horesase_bot.py:229: reply error
Traceback (most recent call last):
  File "horesase_bot.py", line 227, in main
    api.update_with_media('picture.gif', reply_text, in_reply_status_id='user_tweet.id')
  File "/usr/local/lib/python3.4/site-packages/tweepy/api.py", line 231, in update_with_media
    )(*args, **kwargs)
  File "/usr/local/lib/python3.4/site-packages/tweepy/binder.py", line 239, in _call
    return method.execute()
  File "/usr/local/lib/python3.4/site-packages/tweepy/binder.py", line 223, in execute
    raise TweepError(error_msg, resp)
tweepy.error.TweepError: Twitter error response: status code = 403
[2015/07/16 23:00:31]ERROR - horesase_bot.py:229: reply error
Traceback (most recent call last):
  File "horesase_bot.py", line 227, in main
    api.update_with_media('picture.gif', reply_text, in_reply_status_id='user_tweet.id')
  File "/usr/local/lib/python3.4/site-packages/tweepy/api.py", line 231, in update_with_media
    )(*args, **kwargs)
  File "/usr/local/lib/python3.4/site-packages/tweepy/binder.py", line 239, in _call
    return method.execute()
  File "/usr/local/lib/python3.4/site-packages/tweepy/binder.py", line 223, in execute
    raise TweepError(error_msg, resp)
tweepy.error.TweepError: Twitter error response: status code = 403
[2015/07/17 03:00:19]ERROR - horesase_bot.py:229: reply error
Traceback (most recent call last):
  File "horesase_bot.py", line 227, in main
    api.update_with_media('picture.gif', reply_text, in_reply_status_id='user_tweet.id')
  File "/usr/local/lib/python3.4/site-packages/tweepy/api.py", line 231, in update_with_media
    )(*args, **kwargs)
  File "/usr/local/lib/python3.4/site-packages/tweepy/binder.py", line 239, in _call
    return method.execute()
  File "/usr/local/lib/python3.4/site-packages/tweepy/binder.py", line 223, in execute
    raise TweepError(error_msg, resp)
tweepy.error.TweepError: Twitter error response: status code = 403
[2015/07/17 03:00:28]ERROR - horesase_bot.py:229: reply error
Traceback (most recent call last):
  File "horesase_bot.py", line 227, in main
    api.update_with_media('picture.gif', reply_text, in_reply_status_id='user_tweet.id')
  File "/usr/local/lib/python3.4/site-packages/tweepy/api.py", line 231, in update_with_media
    )(*args, **kwargs)
  File "/usr/local/lib/python3.4/site-packages/tweepy/binder.py", line 239, in _call
    return method.execute()
  File "/usr/local/lib/python3.4/site-packages/tweepy/binder.py", line 223, in execute
    raise TweepError(error_msg, resp)
tweepy.error.TweepError: Twitter error response: status code = 403
[2015/07/17 03:00:36]ERROR - horesase_bot.py:229: reply error
Traceback (most recent call last):
  File "horesase_bot.py", line 227, in main
    api.update_with_media('picture.gif', reply_text, in_reply_status_id='user_tweet.id')
  File "/usr/local/lib/python3.4/site-packages/tweepy/api.py", line 231, in update_with_media
    )(*args, **kwargs)
  File "/usr/local/lib/python3.4/site-packages/tweepy/binder.py", line 239, in _call
    return method.execute()
  File "/usr/local/lib/python3.4/site-packages/tweepy/binder.py", line 223, in execute
    raise TweepError(error_msg, resp)
tweepy.error.TweepError: Twitter error response: status code = 403
[2015/07/17 03:00:49]ERROR - horesase_bot.py:229: reply error
Traceback (most recent call last):
  File "horesase_bot.py", line 227, in main
    api.update_with_media('picture.gif', reply_text, in_reply_status_id='user_tweet.id')
  File "/usr/local/lib/python3.4/site-packages/tweepy/api.py", line 231, in update_with_media
    )(*args, **kwargs)
  File "/usr/local/lib/python3.4/site-packages/tweepy/binder.py", line 239, in _call
    return method.execute()
  File "/usr/local/lib/python3.4/site-packages/tweepy/binder.py", line 223, in execute
    raise TweepError(error_msg, resp)
tweepy.error.TweepError: Twitter error response: status code = 403
[2015/07/17 09:00:13]ERROR - horesase_bot.py:229: reply error
Traceback (most recent call last):
  File "horesase_bot.py", line 227, in main
    api.update_with_media('picture.gif', reply_text, in_reply_status_id='user_tweet.id')
  File "/usr/local/lib/python3.4/site-packages/tweepy/api.py", line 231, in update_with_media
    )(*args, **kwargs)
  File "/usr/local/lib/python3.4/site-packages/tweepy/binder.py", line 239, in _call
    return method.execute()
  File "/usr/local/lib/python3.4/site-packages/tweepy/binder.py", line 223, in execute
    raise TweepError(error_msg, resp)
tweepy.error.TweepError: Twitter error response: status code = 403
[2015/07/17 09:00:39]ERROR - horesase_bot.py:229: reply error
Traceback (most recent call last):
  File "horesase_bot.py", line 227, in main
    api.update_with_media('picture.gif', reply_text, in_reply_status_id='user_tweet.id')
  File "/usr/local/lib/python3.4/site-packages/tweepy/api.py", line 231, in update_with_media
    )(*args, **kwargs)
  File "/usr/local/lib/python3.4/site-packages/tweepy/binder.py", line 239, in _call
    return method.execute()
  File "/usr/local/lib/python3.4/site-packages/tweepy/binder.py", line 223, in execute
    raise TweepError(error_msg, resp)
tweepy.error.TweepError: Twitter error response: status code = 403
[2015/07/17 13:00:26]ERROR - horesase_bot.py:229: reply error
Traceback (most recent call last):
  File "horesase_bot.py", line 227, in main
    api.update_with_media('picture.gif', reply_text, in_reply_status_id='user_tweet.id')
  File "/usr/local/lib/python3.4/site-packages/tweepy/api.py", line 231, in update_with_media
    )(*args, **kwargs)
  File "/usr/local/lib/python3.4/site-packages/tweepy/binder.py", line 239, in _call
    return method.execute()
  File "/usr/local/lib/python3.4/site-packages/tweepy/binder.py", line 223, in execute
    raise TweepError(error_msg, resp)
tweepy.error.TweepError: Twitter error response: status code = 403
[2015/07/17 13:00:28]ERROR - horesase_bot.py:229: reply error
Traceback (most recent call last):
  File "horesase_bot.py", line 227, in main
    api.update_with_media('picture.gif', reply_text, in_reply_status_id='user_tweet.id')
  File "/usr/local/lib/python3.4/site-packages/tweepy/api.py", line 231, in update_with_media
    )(*args, **kwargs)
  File "/usr/local/lib/python3.4/site-packages/tweepy/binder.py", line 239, in _call
    return method.execute()
  File "/usr/local/lib/python3.4/site-packages/tweepy/binder.py", line 223, in execute
    raise TweepError(error_msg, resp)
tweepy.error.TweepError: Twitter error response: status code = 403
[2015/07/17 23:00:17]ERROR - horesase_bot.py:229: reply error
Traceback (most recent call last):
  File "horesase_bot.py", line 227, in main
    api.update_with_media('picture.gif', reply_text, in_reply_status_id='user_tweet.id')
  File "/usr/local/lib/python3.4/site-packages/tweepy/api.py", line 231, in update_with_media
    )(*args, **kwargs)
  File "/usr/local/lib/python3.4/site-packages/tweepy/binder.py", line 239, in _call
    return method.execute()
  File "/usr/local/lib/python3.4/site-packages/tweepy/binder.py", line 223, in execute
    raise TweepError(error_msg, resp)
tweepy.error.TweepError: Twitter error response: status code = 403
[2015/07/17 23:00:35]ERROR - horesase_bot.py:229: reply error
Traceback (most recent call last):
  File "horesase_bot.py", line 227, in main
    api.update_with_media('picture.gif', reply_text, in_reply_status_id='user_tweet.id')
  File "/usr/local/lib/python3.4/site-packages/tweepy/api.py", line 231, in update_with_media
    )(*args, **kwargs)
  File "/usr/local/lib/python3.4/site-packages/tweepy/binder.py", line 239, in _call
    return method.execute()
  File "/usr/local/lib/python3.4/site-packages/tweepy/binder.py", line 223, in execute
    raise TweepError(error_msg, resp)
tweepy.error.TweepError: Twitter error response: status code = 403
[2015/07/17 23:00:45]ERROR - horesase_bot.py:229: reply error
Traceback (most recent call last):
  File "horesase_bot.py", line 227, in main
    api.update_with_media('picture.gif', reply_text, in_reply_status_id='user_tweet.id')
  File "/usr/local/lib/python3.4/site-packages/tweepy/api.py", line 231, in update_with_media
    )(*args, **kwargs)
  File "/usr/local/lib/python3.4/site-packages/tweepy/binder.py", line 239, in _call
    return method.execute()
  File "/usr/local/lib/python3.4/site-packages/tweepy/binder.py", line 223, in execute
    raise TweepError(error_msg, resp)
tweepy.error.TweepError: Twitter error response: status code = 403
[2015/07/18 03:00:09]ERROR - horesase_bot.py:229: reply error
Traceback (most recent call last):
  File "horesase_bot.py", line 227, in main
    api.update_with_media('picture.gif', reply_text, in_reply_status_id='user_tweet.id')
  File "/usr/local/lib/python3.4/site-packages/tweepy/api.py", line 231, in update_with_media
    )(*args, **kwargs)
  File "/usr/local/lib/python3.4/site-packages/tweepy/binder.py", line 239, in _call
    return method.execute()
  File "/usr/local/lib/python3.4/site-packages/tweepy/binder.py", line 223, in execute
    raise TweepError(error_msg, resp)
tweepy.error.TweepError: Twitter error response: status code = 403
[2015/07/18 03:00:17]ERROR - horesase_bot.py:229: reply error
Traceback (most recent call last):
  File "horesase_bot.py", line 227, in main
    api.update_with_media('picture.gif', reply_text, in_reply_status_id='user_tweet.id')
  File "/usr/local/lib/python3.4/site-packages/tweepy/api.py", line 231, in update_with_media
    )(*args, **kwargs)
  File "/usr/local/lib/python3.4/site-packages/tweepy/binder.py", line 239, in _call
    return method.execute()
  File "/usr/local/lib/python3.4/site-packages/tweepy/binder.py", line 223, in execute
    raise TweepError(error_msg, resp)
tweepy.error.TweepError: Twitter error response: status code = 403
[2015/07/18 03:00:26]ERROR - horesase_bot.py:229: reply error
Traceback (most recent call last):
  File "horesase_bot.py", line 227, in main
    api.update_with_media('picture.gif', reply_text, in_reply_status_id='user_tweet.id')
  File "/usr/local/lib/python3.4/site-packages/tweepy/api.py", line 231, in update_with_media
    )(*args, **kwargs)
  File "/usr/local/lib/python3.4/site-packages/tweepy/binder.py", line 239, in _call
    return method.execute()
  File "/usr/local/lib/python3.4/site-packages/tweepy/binder.py", line 223, in execute
    raise TweepError(error_msg, resp)
tweepy.error.TweepError: Twitter error response: status code = 403
[2015/07/18 09:00:21]ERROR - horesase_bot.py:229: reply error
Traceback (most recent call last):
  File "horesase_bot.py", line 227, in main
    api.update_with_media('picture.gif', reply_text, in_reply_status_id='user_tweet.id')
  File "/usr/local/lib/python3.4/site-packages/tweepy/api.py", line 231, in update_with_media
    )(*args, **kwargs)
  File "/usr/local/lib/python3.4/site-packages/tweepy/binder.py", line 239, in _call
    return method.execute()
  File "/usr/local/lib/python3.4/site-packages/tweepy/binder.py", line 223, in execute
    raise TweepError(error_msg, resp)
tweepy.error.TweepError: Twitter error response: status code = 403
[2015/07/18 09:00:27]ERROR - horesase_bot.py:229: reply error
Traceback (most recent call last):
  File "horesase_bot.py", line 227, in main
    api.update_with_media('picture.gif', reply_text, in_reply_status_id='user_tweet.id')
  File "/usr/local/lib/python3.4/site-packages/tweepy/api.py", line 231, in update_with_media
    )(*args, **kwargs)
  File "/usr/local/lib/python3.4/site-packages/tweepy/binder.py", line 239, in _call
    return method.execute()
  File "/usr/local/lib/python3.4/site-packages/tweepy/binder.py", line 223, in execute
    raise TweepError(error_msg, resp)
tweepy.error.TweepError: Twitter error response: status code = 403
[2015/07/18 09:00:42]ERROR - horesase_bot.py:229: reply error
Traceback (most recent call last):
  File "horesase_bot.py", line 227, in main
    api.update_with_media('picture.gif', reply_text, in_reply_status_id='user_tweet.id')
  File "/usr/local/lib/python3.4/site-packages/tweepy/api.py", line 231, in update_with_media
    )(*args, **kwargs)
  File "/usr/local/lib/python3.4/site-packages/tweepy/binder.py", line 239, in _call
    return method.execute()
  File "/usr/local/lib/python3.4/site-packages/tweepy/binder.py", line 223, in execute
    raise TweepError(error_msg, resp)
tweepy.error.TweepError: Twitter error response: status code = 403
[2015/07/18 13:00:38]ERROR - horesase_bot.py:229: reply error
Traceback (most recent call last):
  File "horesase_bot.py", line 227, in main
    api.update_with_media('picture.gif', reply_text, in_reply_status_id='user_tweet.id')
  File "/usr/local/lib/python3.4/site-packages/tweepy/api.py", line 231, in update_with_media
    )(*args, **kwargs)
  File "/usr/local/lib/python3.4/site-packages/tweepy/binder.py", line 239, in _call
    return method.execute()
  File "/usr/local/lib/python3.4/site-packages/tweepy/binder.py", line 223, in execute
    raise TweepError(error_msg, resp)
tweepy.error.TweepError: Twitter error response: status code = 403
[2015/07/18 23:00:13]ERROR - horesase_bot.py:229: reply error
Traceback (most recent call last):
  File "horesase_bot.py", line 227, in main
    api.update_with_media('picture.gif', reply_text, in_reply_status_id='user_tweet.id')
  File "/usr/local/lib/python3.4/site-packages/tweepy/api.py", line 231, in update_with_media
    )(*args, **kwargs)
  File "/usr/local/lib/python3.4/site-packages/tweepy/binder.py", line 239, in _call
    return method.execute()
  File "/usr/local/lib/python3.4/site-packages/tweepy/binder.py", line 223, in execute
    raise TweepError(error_msg, resp)
tweepy.error.TweepError: Twitter error response: status code = 403
[2015/07/18 23:00:24]ERROR - horesase_bot.py:229: reply error
Traceback (most recent call last):
  File "horesase_bot.py", line 227, in main
    api.update_with_media('picture.gif', reply_text, in_reply_status_id='user_tweet.id')
  File "/usr/local/lib/python3.4/site-packages/tweepy/api.py", line 231, in update_with_media
    )(*args, **kwargs)
  File "/usr/local/lib/python3.4/site-packages/tweepy/binder.py", line 239, in _call
    return method.execute()
  File "/usr/local/lib/python3.4/site-packages/tweepy/binder.py", line 223, in execute
    raise TweepError(error_msg, resp)
tweepy.error.TweepError: Twitter error response: status code = 403
[2015/07/18 23:00:28]ERROR - horesase_bot.py:229: reply error
Traceback (most recent call last):
  File "horesase_bot.py", line 227, in main
    api.update_with_media('picture.gif', reply_text, in_reply_status_id='user_tweet.id')
  File "/usr/local/lib/python3.4/site-packages/tweepy/api.py", line 231, in update_with_media
    )(*args, **kwargs)
  File "/usr/local/lib/python3.4/site-packages/tweepy/binder.py", line 239, in _call
    return method.execute()
  File "/usr/local/lib/python3.4/site-packages/tweepy/binder.py", line 223, in execute
    raise TweepError(error_msg, resp)
tweepy.error.TweepError: Twitter error response: status code = 403
[2015/07/19 09:00:24]ERROR - horesase_bot.py:229: reply error
Traceback (most recent call last):
  File "horesase_bot.py", line 227, in main
    api.update_with_media('picture.gif', reply_text, in_reply_status_id='user_tweet.id')
  File "/usr/local/lib/python3.4/site-packages/tweepy/api.py", line 231, in update_with_media
    )(*args, **kwargs)
  File "/usr/local/lib/python3.4/site-packages/tweepy/binder.py", line 239, in _call
    return method.execute()
  File "/usr/local/lib/python3.4/site-packages/tweepy/binder.py", line 223, in execute
    raise TweepError(error_msg, resp)
tweepy.error.TweepError: Twitter error response: status code = 403
[2015/07/20 13:00:29]ERROR - horesase_bot.py:236: reply error
Traceback (most recent call last):
  File "horesase_bot.py", line 234, in main
    api.update_with_media('picture.gif', reply_text, in_reply_status_id='user_tweet.id')
  File "/usr/local/lib/python3.4/site-packages/tweepy/api.py", line 231, in update_with_media
    )(*args, **kwargs)
  File "/usr/local/lib/python3.4/site-packages/tweepy/binder.py", line 239, in _call
    return method.execute()
  File "/usr/local/lib/python3.4/site-packages/tweepy/binder.py", line 223, in execute
    raise TweepError(error_msg, resp)
tweepy.error.TweepError: Twitter error response: status code = 403
[2015/07/20 23:00:18]ERROR - horesase_bot.py:236: reply error
Traceback (most recent call last):
  File "horesase_bot.py", line 234, in main
    api.update_with_media('picture.gif', reply_text, in_reply_status_id='user_tweet.id')
  File "/usr/local/lib/python3.4/site-packages/tweepy/api.py", line 231, in update_with_media
    )(*args, **kwargs)
  File "/usr/local/lib/python3.4/site-packages/tweepy/binder.py", line 239, in _call
    return method.execute()
  File "/usr/local/lib/python3.4/site-packages/tweepy/binder.py", line 223, in execute
    raise TweepError(error_msg, resp)
tweepy.error.TweepError: Twitter error response: status code = 403
[2015/07/21 09:00:05]ERROR - horesase_bot.py:236: reply error
Traceback (most recent call last):
  File "horesase_bot.py", line 234, in main
    api.update_with_media('picture.gif', reply_text, in_reply_status_id='user_tweet.id')
  File "/usr/local/lib/python3.4/site-packages/tweepy/api.py", line 231, in update_with_media
    )(*args, **kwargs)
  File "/usr/local/lib/python3.4/site-packages/tweepy/binder.py", line 239, in _call
    return method.execute()
  File "/usr/local/lib/python3.4/site-packages/tweepy/binder.py", line 223, in execute
    raise TweepError(error_msg, resp)
tweepy.error.TweepError: Twitter error response: status code = 403
[2015/07/21 09:00:21]ERROR - horesase_bot.py:236: reply error
Traceback (most recent call last):
  File "horesase_bot.py", line 234, in main
    api.update_with_media('picture.gif', reply_text, in_reply_status_id='user_tweet.id')
  File "/usr/local/lib/python3.4/site-packages/tweepy/api.py", line 231, in update_with_media
    )(*args, **kwargs)
  File "/usr/local/lib/python3.4/site-packages/tweepy/binder.py", line 239, in _call
    return method.execute()
  File "/usr/local/lib/python3.4/site-packages/tweepy/binder.py", line 223, in execute
    raise TweepError(error_msg, resp)
tweepy.error.TweepError: Twitter error response: status code = 403
[2015/07/21 12:47:27]ERROR - horesase_bot.py:240: reply error
Traceback (most recent call last):
  File "horesase_bot.py", line 238, in main
    api.update_status('reply_test', in_reply_to_status_id=user_tweet.id)
  File "/usr/local/lib/python3.4/site-packages/tweepy/api.py", line 193, in update_status
    )(post_data=post_data, *args, **kwargs)
  File "/usr/local/lib/python3.4/site-packages/tweepy/binder.py", line 239, in _call
    return method.execute()
  File "/usr/local/lib/python3.4/site-packages/tweepy/binder.py", line 223, in execute
    raise TweepError(error_msg, resp)
tweepy.error.TweepError: Twitter error response: status code = 400
[2015/07/21 12:48:01]ERROR - horesase_bot.py:240: reply error
Traceback (most recent call last):
  File "horesase_bot.py", line 238, in main
    api.update_status('reply_test', in_reply_status_id=user_tweet.id)
  File "/usr/local/lib/python3.4/site-packages/tweepy/api.py", line 193, in update_status
    )(post_data=post_data, *args, **kwargs)
  File "/usr/local/lib/python3.4/site-packages/tweepy/binder.py", line 239, in _call
    return method.execute()
  File "/usr/local/lib/python3.4/site-packages/tweepy/binder.py", line 223, in execute
    raise TweepError(error_msg, resp)
tweepy.error.TweepError: Twitter error response: status code = 400
[2015/07/21 13:33:32]ERROR - horesase_bot.py:75: api-seach error
Traceback (most recent call last):
  File "horesase_bot.py", line 73, in api_search_user_with_name
    candidate_tweets = api.search(q=at_name)
  File "/usr/local/lib/python3.4/site-packages/tweepy/binder.py", line 239, in _call
    return method.execute()
  File "/usr/local/lib/python3.4/site-packages/tweepy/binder.py", line 187, in execute
    proxies=self.api.proxy)
  File "/usr/local/lib/python3.4/site-packages/requests/sessions.py", line 465, in request
    resp = self.send(prep, **send_kwargs)
  File "/usr/local/lib/python3.4/site-packages/requests/sessions.py", line 573, in send
    r = adapter.send(request, **kwargs)
  File "/usr/local/lib/python3.4/site-packages/requests/adapters.py", line 370, in send
    timeout=timeout
  File "/usr/local/lib/python3.4/site-packages/requests/packages/urllib3/connectionpool.py", line 544, in urlopen
    body=body, headers=headers)
  File "/usr/local/lib/python3.4/site-packages/requests/packages/urllib3/connectionpool.py", line 341, in _make_request
    self._validate_conn(conn)
  File "/usr/local/lib/python3.4/site-packages/requests/packages/urllib3/connectionpool.py", line 761, in _validate_conn
    conn.connect()
  File "/usr/local/lib/python3.4/site-packages/requests/packages/urllib3/connection.py", line 204, in connect
    conn = self._new_conn()
  File "/usr/local/lib/python3.4/site-packages/requests/packages/urllib3/connection.py", line 134, in _new_conn
    (self.host, self.port), self.timeout, **extra_kw)
  File "/usr/local/lib/python3.4/site-packages/requests/packages/urllib3/util/connection.py", line 78, in create_connection
    sock.connect(sa)
KeyboardInterrupt
[2015/07/22 03:00:27]ERROR - horesase_bot.py:236: reply error
Traceback (most recent call last):
  File "horesase_bot.py", line 234, in main
    api.update_with_media('picture.gif', reply_text, in_reply_to_status_id=user_tweet.id)
  File "/usr/local/lib/python3.4/site-packages/tweepy/api.py", line 231, in update_with_media
    )(*args, **kwargs)
  File "/usr/local/lib/python3.4/site-packages/tweepy/binder.py", line 239, in _call
    return method.execute()
  File "/usr/local/lib/python3.4/site-packages/tweepy/binder.py", line 223, in execute
    raise TweepError(error_msg, resp)
tweepy.error.TweepError: Twitter error response: status code = 403
[2015/07/24 03:00:03]ERROR - horesase_bot.py:84: empty pickle file
Traceback (most recent call last):
  File "horesase_bot.py", line 82, in api_search_user_with_name
    stid_dic = pickle.load(f)
EOFError: Ran out of input
[2015/07/24 09:00:03]ERROR - horesase_bot.py:84: empty pickle file
Traceback (most recent call last):
  File "horesase_bot.py", line 82, in api_search_user_with_name
    stid_dic = pickle.load(f)
EOFError: Ran out of input
[2015/07/24 13:00:03]ERROR - horesase_bot.py:84: empty pickle file
Traceback (most recent call last):
  File "horesase_bot.py", line 82, in api_search_user_with_name
    stid_dic = pickle.load(f)
EOFError: Ran out of input
[2015/07/28 08:09:57]ERROR - horesase_bot.py:171: Unexpected Error
Traceback (most recent call last):
  File "horesase_bot.py", line 166, in get_user_text
    retR=True, method=method, model=model, dictionary=dictionary)
  File "/home/ec2-user/horesase/misawa-matcher/matcher_main.py", line 54, in search_misawa
    r = -1.*matutils.cossim(meigen[method], vec)
KeyError: 'lda200'
[2015/07/28 08:09:58]ERROR - horesase_bot.py:171: Unexpected Error
Traceback (most recent call last):
  File "horesase_bot.py", line 166, in get_user_text
    retR=True, method=method, model=model, dictionary=dictionary)
  File "/home/ec2-user/horesase/misawa-matcher/matcher_main.py", line 54, in search_misawa
    r = -1.*matutils.cossim(meigen[method], vec)
KeyError: 'lda200'
[2015/07/28 08:10:00]ERROR - horesase_bot.py:171: Unexpected Error
Traceback (most recent call last):
  File "horesase_bot.py", line 166, in get_user_text
    retR=True, method=method, model=model, dictionary=dictionary)
  File "/home/ec2-user/horesase/misawa-matcher/matcher_main.py", line 54, in search_misawa
    r = -1.*matutils.cossim(meigen[method], vec)
KeyError: 'lda200'
[2015/07/28 08:10:00]ERROR - horesase_bot.py:171: Unexpected Error
Traceback (most recent call last):
  File "horesase_bot.py", line 166, in get_user_text
    retR=True, method=method, model=model, dictionary=dictionary)
  File "/home/ec2-user/horesase/misawa-matcher/matcher_main.py", line 54, in search_misawa
    r = -1.*matutils.cossim(meigen[method], vec)
KeyError: 'lda200'
[2015/07/28 08:10:00]ERROR - horesase_bot.py:171: Unexpected Error
Traceback (most recent call last):
  File "horesase_bot.py", line 166, in get_user_text
    retR=True, method=method, model=model, dictionary=dictionary)
  File "/home/ec2-user/horesase/misawa-matcher/matcher_main.py", line 54, in search_misawa
    r = -1.*matutils.cossim(meigen[method], vec)
KeyError: 'lda200'
[2015/07/28 08:10:00]ERROR - horesase_bot.py:171: Unexpected Error
Traceback (most recent call last):
  File "horesase_bot.py", line 166, in get_user_text
    retR=True, method=method, model=model, dictionary=dictionary)
  File "/home/ec2-user/horesase/misawa-matcher/matcher_main.py", line 54, in search_misawa
    r = -1.*matutils.cossim(meigen[method], vec)
KeyError: 'lda200'
[2015/07/28 08:10:00]ERROR - horesase_bot.py:171: Unexpected Error
Traceback (most recent call last):
  File "horesase_bot.py", line 166, in get_user_text
    retR=True, method=method, model=model, dictionary=dictionary)
  File "/home/ec2-user/horesase/misawa-matcher/matcher_main.py", line 54, in search_misawa
    r = -1.*matutils.cossim(meigen[method], vec)
KeyError: 'lda200'
[2015/07/28 08:10:00]ERROR - horesase_bot.py:171: Unexpected Error
Traceback (most recent call last):
  File "horesase_bot.py", line 166, in get_user_text
    retR=True, method=method, model=model, dictionary=dictionary)
  File "/home/ec2-user/horesase/misawa-matcher/matcher_main.py", line 54, in search_misawa
    r = -1.*matutils.cossim(meigen[method], vec)
KeyError: 'lda200'
[2015/07/28 08:10:00]ERROR - horesase_bot.py:171: Unexpected Error
Traceback (most recent call last):
  File "horesase_bot.py", line 166, in get_user_text
    retR=True, method=method, model=model, dictionary=dictionary)
  File "/home/ec2-user/horesase/misawa-matcher/matcher_main.py", line 54, in search_misawa
    r = -1.*matutils.cossim(meigen[method], vec)
KeyError: 'lda200'
[2015/07/28 08:10:00]ERROR - horesase_bot.py:171: Unexpected Error
Traceback (most recent call last):
  File "horesase_bot.py", line 166, in get_user_text
    retR=True, method=method, model=model, dictionary=dictionary)
  File "/home/ec2-user/horesase/misawa-matcher/matcher_main.py", line 54, in search_misawa
    r = -1.*matutils.cossim(meigen[method], vec)
KeyError: 'lda200'
[2015/07/28 08:10:00]ERROR - horesase_bot.py:171: Unexpected Error
Traceback (most recent call last):
  File "horesase_bot.py", line 166, in get_user_text
    retR=True, method=method, model=model, dictionary=dictionary)
  File "/home/ec2-user/horesase/misawa-matcher/matcher_main.py", line 54, in search_misawa
    r = -1.*matutils.cossim(meigen[method], vec)
KeyError: 'lda200'
[2015/07/28 08:10:00]ERROR - horesase_bot.py:171: Unexpected Error
Traceback (most recent call last):
  File "horesase_bot.py", line 166, in get_user_text
    retR=True, method=method, model=model, dictionary=dictionary)
  File "/home/ec2-user/horesase/misawa-matcher/matcher_main.py", line 54, in search_misawa
    r = -1.*matutils.cossim(meigen[method], vec)
KeyError: 'lda200'
[2015/07/28 08:10:01]ERROR - horesase_bot.py:171: Unexpected Error
Traceback (most recent call last):
  File "horesase_bot.py", line 166, in get_user_text
    retR=True, method=method, model=model, dictionary=dictionary)
  File "/home/ec2-user/horesase/misawa-matcher/matcher_main.py", line 54, in search_misawa
    r = -1.*matutils.cossim(meigen[method], vec)
KeyError: 'lda200'
[2015/07/28 08:10:01]ERROR - horesase_bot.py:171: Unexpected Error
Traceback (most recent call last):
  File "horesase_bot.py", line 166, in get_user_text
    retR=True, method=method, model=model, dictionary=dictionary)
  File "/home/ec2-user/horesase/misawa-matcher/matcher_main.py", line 54, in search_misawa
    r = -1.*matutils.cossim(meigen[method], vec)
KeyError: 'lda200'
[2015/07/28 08:10:01]ERROR - horesase_bot.py:171: Unexpected Error
Traceback (most recent call last):
  File "horesase_bot.py", line 166, in get_user_text
    retR=True, method=method, model=model, dictionary=dictionary)
  File "/home/ec2-user/horesase/misawa-matcher/matcher_main.py", line 54, in search_misawa
    r = -1.*matutils.cossim(meigen[method], vec)
KeyError: 'lda200'
[2015/07/28 08:10:07]ERROR - horesase_bot.py:171: Unexpected Error
Traceback (most recent call last):
  File "horesase_bot.py", line 166, in get_user_text
    retR=True, method=method, model=model, dictionary=dictionary)
  File "/home/ec2-user/horesase/misawa-matcher/matcher_main.py", line 54, in search_misawa
    r = -1.*matutils.cossim(meigen[method], vec)
KeyError: 'lda200'
[2015/07/28 08:10:09]ERROR - horesase_bot.py:171: Unexpected Error
Traceback (most recent call last):
  File "horesase_bot.py", line 166, in get_user_text
    retR=True, method=method, model=model, dictionary=dictionary)
  File "/home/ec2-user/horesase/misawa-matcher/matcher_main.py", line 54, in search_misawa
    r = -1.*matutils.cossim(meigen[method], vec)
KeyError: 'lda200'
[2015/07/28 08:10:09]ERROR - horesase_bot.py:171: Unexpected Error
Traceback (most recent call last):
  File "horesase_bot.py", line 166, in get_user_text
    retR=True, method=method, model=model, dictionary=dictionary)
  File "/home/ec2-user/horesase/misawa-matcher/matcher_main.py", line 54, in search_misawa
    r = -1.*matutils.cossim(meigen[method], vec)
KeyError: 'lda200'
[2015/07/28 08:10:09]ERROR - horesase_bot.py:171: Unexpected Error
Traceback (most recent call last):
  File "horesase_bot.py", line 166, in get_user_text
    retR=True, method=method, model=model, dictionary=dictionary)
  File "/home/ec2-user/horesase/misawa-matcher/matcher_main.py", line 54, in search_misawa
    r = -1.*matutils.cossim(meigen[method], vec)
KeyError: 'lda200'
[2015/07/28 08:10:09]ERROR - horesase_bot.py:171: Unexpected Error
Traceback (most recent call last):
  File "horesase_bot.py", line 166, in get_user_text
    retR=True, method=method, model=model, dictionary=dictionary)
  File "/home/ec2-user/horesase/misawa-matcher/matcher_main.py", line 54, in search_misawa
    r = -1.*matutils.cossim(meigen[method], vec)
KeyError: 'lda200'
[2015/07/28 08:10:09]ERROR - horesase_bot.py:171: Unexpected Error
Traceback (most recent call last):
  File "horesase_bot.py", line 166, in get_user_text
    retR=True, method=method, model=model, dictionary=dictionary)
  File "/home/ec2-user/horesase/misawa-matcher/matcher_main.py", line 54, in search_misawa
    r = -1.*matutils.cossim(meigen[method], vec)
KeyError: 'lda200'
[2015/07/28 08:10:09]ERROR - horesase_bot.py:171: Unexpected Error
Traceback (most recent call last):
  File "horesase_bot.py", line 166, in get_user_text
    retR=True, method=method, model=model, dictionary=dictionary)
  File "/home/ec2-user/horesase/misawa-matcher/matcher_main.py", line 54, in search_misawa
    r = -1.*matutils.cossim(meigen[method], vec)
KeyError: 'lda200'
[2015/07/28 08:10:09]ERROR - horesase_bot.py:171: Unexpected Error
Traceback (most recent call last):
  File "horesase_bot.py", line 166, in get_user_text
    retR=True, method=method, model=model, dictionary=dictionary)
  File "/home/ec2-user/horesase/misawa-matcher/matcher_main.py", line 54, in search_misawa
    r = -1.*matutils.cossim(meigen[method], vec)
KeyError: 'lda200'
[2015/07/28 08:10:10]ERROR - horesase_bot.py:171: Unexpected Error
Traceback (most recent call last):
  File "horesase_bot.py", line 166, in get_user_text
    retR=True, method=method, model=model, dictionary=dictionary)
  File "/home/ec2-user/horesase/misawa-matcher/matcher_main.py", line 54, in search_misawa
    r = -1.*matutils.cossim(meigen[method], vec)
KeyError: 'lda200'
[2015/07/28 08:10:12]ERROR - horesase_bot.py:171: Unexpected Error
Traceback (most recent call last):
  File "horesase_bot.py", line 166, in get_user_text
    retR=True, method=method, model=model, dictionary=dictionary)
  File "/home/ec2-user/horesase/misawa-matcher/matcher_main.py", line 54, in search_misawa
    r = -1.*matutils.cossim(meigen[method], vec)
KeyError: 'lda200'
[2015/07/28 08:10:12]ERROR - horesase_bot.py:171: Unexpected Error
Traceback (most recent call last):
  File "horesase_bot.py", line 166, in get_user_text
    retR=True, method=method, model=model, dictionary=dictionary)
  File "/home/ec2-user/horesase/misawa-matcher/matcher_main.py", line 54, in search_misawa
    r = -1.*matutils.cossim(meigen[method], vec)
KeyError: 'lda200'
[2015/07/28 08:10:14]CRITICAL - horesase_bot.py:138: user_timeline fetch error
Traceback (most recent call last):
  File "horesase_bot.py", line 136, in get_user_text
    user_tweets = api.user_timeline(id=user, count=20)
  File "/usr/local/lib/python3.4/site-packages/tweepy/binder.py", line 239, in _call
    return method.execute()
  File "/usr/local/lib/python3.4/site-packages/tweepy/binder.py", line 187, in execute
    proxies=self.api.proxy)
  File "/usr/local/lib/python3.4/site-packages/requests/sessions.py", line 465, in request
    resp = self.send(prep, **send_kwargs)
  File "/usr/local/lib/python3.4/site-packages/requests/sessions.py", line 573, in send
    r = adapter.send(request, **kwargs)
  File "/usr/local/lib/python3.4/site-packages/requests/adapters.py", line 370, in send
    timeout=timeout
  File "/usr/local/lib/python3.4/site-packages/requests/packages/urllib3/connectionpool.py", line 544, in urlopen
    body=body, headers=headers)
  File "/usr/local/lib/python3.4/site-packages/requests/packages/urllib3/connectionpool.py", line 341, in _make_request
    self._validate_conn(conn)
  File "/usr/local/lib/python3.4/site-packages/requests/packages/urllib3/connectionpool.py", line 761, in _validate_conn
    conn.connect()
  File "/usr/local/lib/python3.4/site-packages/requests/packages/urllib3/connection.py", line 238, in connect
    ssl_version=resolved_ssl_version)
  File "/usr/local/lib/python3.4/site-packages/requests/packages/urllib3/util/ssl_.py", line 279, in ssl_wrap_socket
    return context.wrap_socket(sock, server_hostname=server_hostname)
  File "/usr/local/lib/python3.4/ssl.py", line 365, in wrap_socket
    _context=self)
  File "/usr/local/lib/python3.4/ssl.py", line 583, in __init__
    self.do_handshake()
  File "/usr/local/lib/python3.4/ssl.py", line 810, in do_handshake
    self._sslobj.do_handshake()
KeyboardInterrupt
[2015/07/28 08:12:17]ERROR - horesase_bot.py:171: Unexpected Error
Traceback (most recent call last):
  File "horesase_bot.py", line 166, in get_user_text
    retR=True, method=method, model=model, dictionary=dictionary)
  File "/home/ec2-user/horesase/misawa-matcher/matcher_main.py", line 54, in search_misawa
    r = -1.*matutils.cossim(meigen[method], vec)
KeyError: 'lda200'
[2015/07/28 08:12:20]ERROR - horesase_bot.py:171: Unexpected Error
Traceback (most recent call last):
  File "horesase_bot.py", line 166, in get_user_text
    retR=True, method=method, model=model, dictionary=dictionary)
  File "/home/ec2-user/horesase/misawa-matcher/matcher_main.py", line 54, in search_misawa
    r = -1.*matutils.cossim(meigen[method], vec)
KeyError: 'lda200'
[2015/07/28 08:12:20]ERROR - horesase_bot.py:171: Unexpected Error
Traceback (most recent call last):
  File "horesase_bot.py", line 166, in get_user_text
    retR=True, method=method, model=model, dictionary=dictionary)
  File "/home/ec2-user/horesase/misawa-matcher/matcher_main.py", line 54, in search_misawa
    r = -1.*matutils.cossim(meigen[method], vec)
KeyError: 'lda200'
[2015/07/28 08:12:20]ERROR - horesase_bot.py:171: Unexpected Error
Traceback (most recent call last):
  File "horesase_bot.py", line 166, in get_user_text
    retR=True, method=method, model=model, dictionary=dictionary)
  File "/home/ec2-user/horesase/misawa-matcher/matcher_main.py", line 54, in search_misawa
    r = -1.*matutils.cossim(meigen[method], vec)
KeyError: 'lda200'
[2015/07/28 08:12:20]ERROR - horesase_bot.py:171: Unexpected Error
Traceback (most recent call last):
  File "horesase_bot.py", line 166, in get_user_text
    retR=True, method=method, model=model, dictionary=dictionary)
  File "/home/ec2-user/horesase/misawa-matcher/matcher_main.py", line 54, in search_misawa
    r = -1.*matutils.cossim(meigen[method], vec)
KeyError: 'lda200'
[2015/07/28 08:12:20]ERROR - horesase_bot.py:171: Unexpected Error
Traceback (most recent call last):
  File "horesase_bot.py", line 166, in get_user_text
    retR=True, method=method, model=model, dictionary=dictionary)
  File "/home/ec2-user/horesase/misawa-matcher/matcher_main.py", line 54, in search_misawa
    r = -1.*matutils.cossim(meigen[method], vec)
KeyError: 'lda200'
[2015/07/28 08:12:22]ERROR - horesase_bot.py:171: Unexpected Error
Traceback (most recent call last):
  File "horesase_bot.py", line 166, in get_user_text
    retR=True, method=method, model=model, dictionary=dictionary)
  File "/home/ec2-user/horesase/misawa-matcher/matcher_main.py", line 54, in search_misawa
    r = -1.*matutils.cossim(meigen[method], vec)
KeyError: 'lda200'
[2015/07/28 08:12:22]ERROR - horesase_bot.py:171: Unexpected Error
Traceback (most recent call last):
  File "horesase_bot.py", line 166, in get_user_text
    retR=True, method=method, model=model, dictionary=dictionary)
  File "/home/ec2-user/horesase/misawa-matcher/matcher_main.py", line 54, in search_misawa
    r = -1.*matutils.cossim(meigen[method], vec)
KeyError: 'lda200'
[2015/07/28 08:12:27]ERROR - horesase_bot.py:171: Unexpected Error
Traceback (most recent call last):
  File "horesase_bot.py", line 166, in get_user_text
    retR=True, method=method, model=model, dictionary=dictionary)
  File "/home/ec2-user/horesase/misawa-matcher/matcher_main.py", line 54, in search_misawa
    r = -1.*matutils.cossim(meigen[method], vec)
KeyError: 'lda200'
[2015/07/28 08:12:27]ERROR - horesase_bot.py:171: Unexpected Error
Traceback (most recent call last):
  File "horesase_bot.py", line 166, in get_user_text
    retR=True, method=method, model=model, dictionary=dictionary)
  File "/home/ec2-user/horesase/misawa-matcher/matcher_main.py", line 54, in search_misawa
    r = -1.*matutils.cossim(meigen[method], vec)
KeyError: 'lda200'
[2015/07/28 08:12:27]ERROR - horesase_bot.py:171: Unexpected Error
Traceback (most recent call last):
  File "horesase_bot.py", line 166, in get_user_text
    retR=True, method=method, model=model, dictionary=dictionary)
  File "/home/ec2-user/horesase/misawa-matcher/matcher_main.py", line 54, in search_misawa
    r = -1.*matutils.cossim(meigen[method], vec)
KeyError: 'lda200'
[2015/07/28 08:12:27]ERROR - horesase_bot.py:171: Unexpected Error
Traceback (most recent call last):
  File "horesase_bot.py", line 166, in get_user_text
    retR=True, method=method, model=model, dictionary=dictionary)
  File "/home/ec2-user/horesase/misawa-matcher/matcher_main.py", line 54, in search_misawa
    r = -1.*matutils.cossim(meigen[method], vec)
KeyError: 'lda200'
[2015/07/28 08:12:27]ERROR - horesase_bot.py:171: Unexpected Error
Traceback (most recent call last):
  File "horesase_bot.py", line 166, in get_user_text
    retR=True, method=method, model=model, dictionary=dictionary)
  File "/home/ec2-user/horesase/misawa-matcher/matcher_main.py", line 54, in search_misawa
    r = -1.*matutils.cossim(meigen[method], vec)
KeyError: 'lda200'
[2015/07/28 08:12:27]ERROR - horesase_bot.py:171: Unexpected Error
Traceback (most recent call last):
  File "horesase_bot.py", line 166, in get_user_text
    retR=True, method=method, model=model, dictionary=dictionary)
  File "/home/ec2-user/horesase/misawa-matcher/matcher_main.py", line 54, in search_misawa
    r = -1.*matutils.cossim(meigen[method], vec)
KeyError: 'lda200'
[2015/07/28 08:12:28]ERROR - horesase_bot.py:171: Unexpected Error
Traceback (most recent call last):
  File "horesase_bot.py", line 166, in get_user_text
    retR=True, method=method, model=model, dictionary=dictionary)
  File "/home/ec2-user/horesase/misawa-matcher/matcher_main.py", line 54, in search_misawa
    r = -1.*matutils.cossim(meigen[method], vec)
KeyError: 'lda200'
[2015/07/28 08:12:28]ERROR - horesase_bot.py:171: Unexpected Error
Traceback (most recent call last):
  File "horesase_bot.py", line 166, in get_user_text
    retR=True, method=method, model=model, dictionary=dictionary)
  File "/home/ec2-user/horesase/misawa-matcher/matcher_main.py", line 54, in search_misawa
    r = -1.*matutils.cossim(meigen[method], vec)
KeyError: 'lda200'
[2015/07/28 08:12:28]ERROR - horesase_bot.py:171: Unexpected Error
Traceback (most recent call last):
  File "horesase_bot.py", line 166, in get_user_text
    retR=True, method=method, model=model, dictionary=dictionary)
  File "/home/ec2-user/horesase/misawa-matcher/matcher_main.py", line 54, in search_misawa
    r = -1.*matutils.cossim(meigen[method], vec)
KeyError: 'lda200'
[2015/07/28 08:12:28]ERROR - horesase_bot.py:171: Unexpected Error
Traceback (most recent call last):
  File "horesase_bot.py", line 166, in get_user_text
    retR=True, method=method, model=model, dictionary=dictionary)
  File "/home/ec2-user/horesase/misawa-matcher/matcher_main.py", line 54, in search_misawa
    r = -1.*matutils.cossim(meigen[method], vec)
KeyError: 'lda200'
[2015/07/28 08:12:28]ERROR - horesase_bot.py:171: Unexpected Error
Traceback (most recent call last):
  File "horesase_bot.py", line 166, in get_user_text
    retR=True, method=method, model=model, dictionary=dictionary)
  File "/home/ec2-user/horesase/misawa-matcher/matcher_main.py", line 54, in search_misawa
    r = -1.*matutils.cossim(meigen[method], vec)
KeyError: 'lda200'
[2015/07/28 08:12:28]ERROR - horesase_bot.py:171: Unexpected Error
Traceback (most recent call last):
  File "horesase_bot.py", line 166, in get_user_text
    retR=True, method=method, model=model, dictionary=dictionary)
  File "/home/ec2-user/horesase/misawa-matcher/matcher_main.py", line 54, in search_misawa
    r = -1.*matutils.cossim(meigen[method], vec)
KeyError: 'lda200'
[2015/07/28 08:12:28]ERROR - horesase_bot.py:171: Unexpected Error
Traceback (most recent call last):
  File "horesase_bot.py", line 166, in get_user_text
    retR=True, method=method, model=model, dictionary=dictionary)
  File "/home/ec2-user/horesase/misawa-matcher/matcher_main.py", line 54, in search_misawa
    r = -1.*matutils.cossim(meigen[method], vec)
KeyError: 'lda200'
[2015/07/28 08:12:28]ERROR - horesase_bot.py:171: Unexpected Error
Traceback (most recent call last):
  File "horesase_bot.py", line 166, in get_user_text
    retR=True, method=method, model=model, dictionary=dictionary)
  File "/home/ec2-user/horesase/misawa-matcher/matcher_main.py", line 54, in search_misawa
    r = -1.*matutils.cossim(meigen[method], vec)
KeyError: 'lda200'
[2015/07/28 08:12:29]ERROR - horesase_bot.py:171: Unexpected Error
Traceback (most recent call last):
  File "horesase_bot.py", line 166, in get_user_text
    retR=True, method=method, model=model, dictionary=dictionary)
  File "/home/ec2-user/horesase/misawa-matcher/matcher_main.py", line 54, in search_misawa
    r = -1.*matutils.cossim(meigen[method], vec)
KeyError: 'lda200'
[2015/07/28 08:12:30]ERROR - horesase_bot.py:171: Unexpected Error
Traceback (most recent call last):
  File "horesase_bot.py", line 166, in get_user_text
    retR=True, method=method, model=model, dictionary=dictionary)
  File "/home/ec2-user/horesase/misawa-matcher/matcher_main.py", line 54, in search_misawa
    r = -1.*matutils.cossim(meigen[method], vec)
KeyError: 'lda200'
[2015/07/28 08:12:35]CRITICAL - horesase_bot.py:138: user_timeline fetch error
Traceback (most recent call last):
  File "horesase_bot.py", line 136, in get_user_text
    user_tweets = api.user_timeline(id=user, count=20)
  File "/usr/local/lib/python3.4/site-packages/tweepy/binder.py", line 239, in _call
    return method.execute()
  File "/usr/local/lib/python3.4/site-packages/tweepy/binder.py", line 187, in execute
    proxies=self.api.proxy)
  File "/usr/local/lib/python3.4/site-packages/requests/sessions.py", line 465, in request
    resp = self.send(prep, **send_kwargs)
  File "/usr/local/lib/python3.4/site-packages/requests/sessions.py", line 605, in send
    r.content
  File "/usr/local/lib/python3.4/site-packages/requests/models.py", line 750, in content
    self._content = bytes().join(self.iter_content(CONTENT_CHUNK_SIZE)) or bytes()
  File "/usr/local/lib/python3.4/site-packages/requests/models.py", line 673, in generate
    for chunk in self.raw.stream(chunk_size, decode_content=True):
  File "/usr/local/lib/python3.4/site-packages/requests/packages/urllib3/response.py", line 307, in stream
    data = self.read(amt=amt, decode_content=decode_content)
  File "/usr/local/lib/python3.4/site-packages/requests/packages/urllib3/response.py", line 243, in read
    data = self._fp.read(amt)
  File "/usr/local/lib/python3.4/http/client.py", line 500, in read
    return super(HTTPResponse, self).read(amt)
  File "/usr/local/lib/python3.4/http/client.py", line 539, in readinto
    n = self.fp.readinto(b)
  File "/usr/local/lib/python3.4/socket.py", line 374, in readinto
    return self._sock.recv_into(b)
  File "/usr/local/lib/python3.4/ssl.py", line 751, in recv_into
    return self.read(nbytes, buffer)
  File "/usr/local/lib/python3.4/ssl.py", line 623, in read
    v = self._sslobj.read(len, buffer)
KeyboardInterrupt
[2015/07/28 09:00:28]ERROR - horesase_bot.py:270: reply error
Traceback (most recent call last):
  File "horesase_bot.py", line 267, in main
    api.update_with_media('data/picture.gif', reply_text, in_reply_to_status_id=user_tweet.id)
  File "/usr/local/lib/python3.4/site-packages/tweepy/api.py", line 231, in update_with_media
    )(*args, **kwargs)
  File "/usr/local/lib/python3.4/site-packages/tweepy/binder.py", line 239, in _call
    return method.execute()
  File "/usr/local/lib/python3.4/site-packages/tweepy/binder.py", line 223, in execute
    raise TweepError(error_msg, resp)
tweepy.error.TweepError: Twitter error response: status code = 403
[2015/07/28 09:01:30]ERROR - horesase_bot.py:270: reply error
Traceback (most recent call last):
  File "horesase_bot.py", line 267, in main
    api.update_with_media('data/picture.gif', reply_text, in_reply_to_status_id=user_tweet.id)
  File "/usr/local/lib/python3.4/site-packages/tweepy/api.py", line 231, in update_with_media
    )(*args, **kwargs)
  File "/usr/local/lib/python3.4/site-packages/tweepy/binder.py", line 239, in _call
    return method.execute()
  File "/usr/local/lib/python3.4/site-packages/tweepy/binder.py", line 223, in execute
    raise TweepError(error_msg, resp)
tweepy.error.TweepError: Twitter error response: status code = 403
[2015/07/28 13:00:22]ERROR - horesase_bot.py:270: reply error
Traceback (most recent call last):
  File "horesase_bot.py", line 267, in main
    api.update_with_media('data/picture.gif', reply_text, in_reply_to_status_id=user_tweet.id)
  File "/usr/local/lib/python3.4/site-packages/tweepy/api.py", line 231, in update_with_media
    )(*args, **kwargs)
  File "/usr/local/lib/python3.4/site-packages/tweepy/binder.py", line 239, in _call
    return method.execute()
  File "/usr/local/lib/python3.4/site-packages/tweepy/binder.py", line 223, in execute
    raise TweepError(error_msg, resp)
tweepy.error.TweepError: Twitter error response: status code = 403
[2015/07/28 13:00:42]ERROR - horesase_bot.py:270: reply error
Traceback (most recent call last):
  File "horesase_bot.py", line 267, in main
    api.update_with_media('data/picture.gif', reply_text, in_reply_to_status_id=user_tweet.id)
  File "/usr/local/lib/python3.4/site-packages/tweepy/api.py", line 231, in update_with_media
    )(*args, **kwargs)
  File "/usr/local/lib/python3.4/site-packages/tweepy/binder.py", line 239, in _call
    return method.execute()
  File "/usr/local/lib/python3.4/site-packages/tweepy/binder.py", line 223, in execute
    raise TweepError(error_msg, resp)
tweepy.error.TweepError: Twitter error response: status code = 403
[2015/07/29 02:34:17]ERROR - horesase_bot.py:270: reply error
Traceback (most recent call last):
  File "horesase_bot.py", line 267, in main
    api.update_with_media('data/picture.gif', reply_text, in_reply_to_status_id=user_tweet.id)
  File "/usr/local/lib/python3.4/site-packages/tweepy/api.py", line 231, in update_with_media
    )(*args, **kwargs)
  File "/usr/local/lib/python3.4/site-packages/tweepy/binder.py", line 239, in _call
    return method.execute()
  File "/usr/local/lib/python3.4/site-packages/tweepy/binder.py", line 223, in execute
    raise TweepError(error_msg, resp)
tweepy.error.TweepError: Twitter error response: status code = 403
[2015/07/29 03:01:13]ERROR - horesase_bot.py:270: reply error
Traceback (most recent call last):
  File "horesase_bot.py", line 267, in main
    api.update_with_media('data/picture.gif', reply_text, in_reply_to_status_id=user_tweet.id)
  File "/usr/local/lib/python3.4/site-packages/tweepy/api.py", line 231, in update_with_media
    )(*args, **kwargs)
  File "/usr/local/lib/python3.4/site-packages/tweepy/binder.py", line 239, in _call
    return method.execute()
  File "/usr/local/lib/python3.4/site-packages/tweepy/binder.py", line 223, in execute
    raise TweepError(error_msg, resp)
tweepy.error.TweepError: Twitter error response: status code = 403
[2015/07/29 09:00:55]ERROR - horesase_bot.py:270: reply error
Traceback (most recent call last):
  File "horesase_bot.py", line 267, in main
    api.update_with_media('data/picture.gif', reply_text, in_reply_to_status_id=user_tweet.id)
  File "/usr/local/lib/python3.4/site-packages/tweepy/api.py", line 231, in update_with_media
    )(*args, **kwargs)
  File "/usr/local/lib/python3.4/site-packages/tweepy/binder.py", line 239, in _call
    return method.execute()
  File "/usr/local/lib/python3.4/site-packages/tweepy/binder.py", line 223, in execute
    raise TweepError(error_msg, resp)
tweepy.error.TweepError: Twitter error response: status code = 403
[2015/07/29 13:00:18]ERROR - horesase_bot.py:277: reply error
Traceback (most recent call last):
  File "horesase_bot.py", line 274, in main
    api.update_with_media('data/picture.gif', reply_text, in_reply_to_status_id=user_tweet.id)
  File "/usr/local/lib/python3.4/site-packages/tweepy/api.py", line 231, in update_with_media
    )(*args, **kwargs)
  File "/usr/local/lib/python3.4/site-packages/tweepy/binder.py", line 239, in _call
    return method.execute()
  File "/usr/local/lib/python3.4/site-packages/tweepy/binder.py", line 223, in execute
    raise TweepError(error_msg, resp)
tweepy.error.TweepError: Twitter error response: status code = 403
[2015/07/29 13:01:32]ERROR - horesase_bot.py:277: reply error
Traceback (most recent call last):
  File "horesase_bot.py", line 274, in main
    api.update_with_media('data/picture.gif', reply_text, in_reply_to_status_id=user_tweet.id)
  File "/usr/local/lib/python3.4/site-packages/tweepy/api.py", line 231, in update_with_media
    )(*args, **kwargs)
  File "/usr/local/lib/python3.4/site-packages/tweepy/binder.py", line 239, in _call
    return method.execute()
  File "/usr/local/lib/python3.4/site-packages/tweepy/binder.py", line 223, in execute
    raise TweepError(error_msg, resp)
tweepy.error.TweepError: Twitter error response: status code = 403
[2015/07/29 23:00:11]ERROR - horesase_bot.py:277: reply error
Traceback (most recent call last):
  File "horesase_bot.py", line 274, in main
    api.update_with_media('data/picture.gif', reply_text, in_reply_to_status_id=user_tweet.id)
  File "/usr/local/lib/python3.4/site-packages/tweepy/api.py", line 231, in update_with_media
    )(*args, **kwargs)
  File "/usr/local/lib/python3.4/site-packages/tweepy/binder.py", line 239, in _call
    return method.execute()
  File "/usr/local/lib/python3.4/site-packages/tweepy/binder.py", line 223, in execute
    raise TweepError(error_msg, resp)
tweepy.error.TweepError: Twitter error response: status code = 403
[2015/07/29 23:01:06]ERROR - horesase_bot.py:277: reply error
Traceback (most recent call last):
  File "horesase_bot.py", line 274, in main
    api.update_with_media('data/picture.gif', reply_text, in_reply_to_status_id=user_tweet.id)
  File "/usr/local/lib/python3.4/site-packages/tweepy/api.py", line 231, in update_with_media
    )(*args, **kwargs)
  File "/usr/local/lib/python3.4/site-packages/tweepy/binder.py", line 239, in _call
    return method.execute()
  File "/usr/local/lib/python3.4/site-packages/tweepy/binder.py", line 223, in execute
    raise TweepError(error_msg, resp)
tweepy.error.TweepError: Twitter error response: status code = 403
[2015/07/29 23:01:50]ERROR - horesase_bot.py:277: reply error
Traceback (most recent call last):
  File "horesase_bot.py", line 274, in main
    api.update_with_media('data/picture.gif', reply_text, in_reply_to_status_id=user_tweet.id)
  File "/usr/local/lib/python3.4/site-packages/tweepy/api.py", line 231, in update_with_media
    )(*args, **kwargs)
  File "/usr/local/lib/python3.4/site-packages/tweepy/binder.py", line 239, in _call
    return method.execute()
  File "/usr/local/lib/python3.4/site-packages/tweepy/binder.py", line 223, in execute
    raise TweepError(error_msg, resp)
tweepy.error.TweepError: Twitter error response: status code = 403
[2015/07/29 23:01:54]CRITICAL - horesase_bot.py:138: user_timeline fetch error
Traceback (most recent call last):
  File "horesase_bot.py", line 136, in get_user_text
    user_tweets = api.user_timeline(id=user, count=20)
  File "/usr/local/lib/python3.4/site-packages/tweepy/binder.py", line 239, in _call
    return method.execute()
  File "/usr/local/lib/python3.4/site-packages/tweepy/binder.py", line 223, in execute
    raise TweepError(error_msg, resp)
tweepy.error.TweepError: Twitter error response: status code = 401
[2015/07/30 03:00:49]ERROR - horesase_bot.py:277: reply error
Traceback (most recent call last):
  File "horesase_bot.py", line 274, in main
    api.update_with_media('data/picture.gif', reply_text, in_reply_to_status_id=user_tweet.id)
  File "/usr/local/lib/python3.4/site-packages/tweepy/api.py", line 231, in update_with_media
    )(*args, **kwargs)
  File "/usr/local/lib/python3.4/site-packages/tweepy/binder.py", line 239, in _call
    return method.execute()
  File "/usr/local/lib/python3.4/site-packages/tweepy/binder.py", line 223, in execute
    raise TweepError(error_msg, resp)
tweepy.error.TweepError: Twitter error response: status code = 403
[2015/07/30 03:01:09]CRITICAL - horesase_bot.py:138: user_timeline fetch error
Traceback (most recent call last):
  File "horesase_bot.py", line 136, in get_user_text
    user_tweets = api.user_timeline(id=user, count=20)
  File "/usr/local/lib/python3.4/site-packages/tweepy/binder.py", line 239, in _call
    return method.execute()
  File "/usr/local/lib/python3.4/site-packages/tweepy/binder.py", line 223, in execute
    raise TweepError(error_msg, resp)
tweepy.error.TweepError: Twitter error response: status code = 401
[2015/07/30 09:00:37]CRITICAL - horesase_bot.py:138: user_timeline fetch error
Traceback (most recent call last):
  File "horesase_bot.py", line 136, in get_user_text
    user_tweets = api.user_timeline(id=user, count=20)
  File "/usr/local/lib/python3.4/site-packages/tweepy/binder.py", line 239, in _call
    return method.execute()
  File "/usr/local/lib/python3.4/site-packages/tweepy/binder.py", line 223, in execute
    raise TweepError(error_msg, resp)
tweepy.error.TweepError: Twitter error response: status code = 401
[2015/07/30 13:01:25]ERROR - horesase_bot.py:278: reply error
Traceback (most recent call last):
  File "horesase_bot.py", line 275, in main
    api.update_with_media('data/picture.gif', reply_text, in_reply_to_status_id=user_tweet.id)
  File "/usr/local/lib/python3.4/site-packages/tweepy/api.py", line 231, in update_with_media
    )(*args, **kwargs)
  File "/usr/local/lib/python3.4/site-packages/tweepy/binder.py", line 239, in _call
    return method.execute()
  File "/usr/local/lib/python3.4/site-packages/tweepy/binder.py", line 223, in execute
    raise TweepError(error_msg, resp)
tweepy.error.TweepError: Twitter error response: status code = 403
[2015/07/30 13:01:32]CRITICAL - horesase_bot.py:138: user_timeline fetch error
Traceback (most recent call last):
  File "horesase_bot.py", line 136, in get_user_text
    user_tweets = api.user_timeline(id=user, count=20)
  File "/usr/local/lib/python3.4/site-packages/tweepy/binder.py", line 239, in _call
    return method.execute()
  File "/usr/local/lib/python3.4/site-packages/tweepy/binder.py", line 223, in execute
    raise TweepError(error_msg, resp)
tweepy.error.TweepError: Twitter error response: status code = 401
[2015/07/30 13:01:38]ERROR - horesase_bot.py:278: reply error
Traceback (most recent call last):
  File "horesase_bot.py", line 275, in main
    api.update_with_media('data/picture.gif', reply_text, in_reply_to_status_id=user_tweet.id)
  File "/usr/local/lib/python3.4/site-packages/tweepy/api.py", line 231, in update_with_media
    )(*args, **kwargs)
  File "/usr/local/lib/python3.4/site-packages/tweepy/binder.py", line 239, in _call
    return method.execute()
  File "/usr/local/lib/python3.4/site-packages/tweepy/binder.py", line 223, in execute
    raise TweepError(error_msg, resp)
tweepy.error.TweepError: Twitter error response: status code = 403
[2015/07/30 23:00:51]CRITICAL - horesase_bot.py:138: user_timeline fetch error
Traceback (most recent call last):
  File "horesase_bot.py", line 136, in get_user_text
    user_tweets = api.user_timeline(id=user, count=20)
  File "/usr/local/lib/python3.4/site-packages/tweepy/binder.py", line 239, in _call
    return method.execute()
  File "/usr/local/lib/python3.4/site-packages/tweepy/binder.py", line 223, in execute
    raise TweepError(error_msg, resp)
tweepy.error.TweepError: Twitter error response: status code = 401
[2015/07/31 03:00:08]CRITICAL - horesase_bot.py:138: user_timeline fetch error
Traceback (most recent call last):
  File "horesase_bot.py", line 136, in get_user_text
    user_tweets = api.user_timeline(id=user, count=20)
  File "/usr/local/lib/python3.4/site-packages/tweepy/binder.py", line 239, in _call
    return method.execute()
  File "/usr/local/lib/python3.4/site-packages/tweepy/binder.py", line 223, in execute
    raise TweepError(error_msg, resp)
tweepy.error.TweepError: Twitter error response: status code = 401
[2015/07/31 03:00:57]ERROR - horesase_bot.py:278: reply error
Traceback (most recent call last):
  File "horesase_bot.py", line 275, in main
    api.update_with_media('data/picture.gif', reply_text, in_reply_to_status_id=user_tweet.id)
  File "/usr/local/lib/python3.4/site-packages/tweepy/api.py", line 231, in update_with_media
    )(*args, **kwargs)
  File "/usr/local/lib/python3.4/site-packages/tweepy/binder.py", line 239, in _call
    return method.execute()
  File "/usr/local/lib/python3.4/site-packages/tweepy/binder.py", line 223, in execute
    raise TweepError(error_msg, resp)
tweepy.error.TweepError: Twitter error response: status code = 403
[2015/07/31 09:01:36]ERROR - horesase_bot.py:278: reply error
Traceback (most recent call last):
  File "horesase_bot.py", line 275, in main
    api.update_with_media('data/picture.gif', reply_text, in_reply_to_status_id=user_tweet.id)
  File "/usr/local/lib/python3.4/site-packages/tweepy/api.py", line 231, in update_with_media
    )(*args, **kwargs)
  File "/usr/local/lib/python3.4/site-packages/tweepy/binder.py", line 239, in _call
    return method.execute()
  File "/usr/local/lib/python3.4/site-packages/tweepy/binder.py", line 223, in execute
    raise TweepError(error_msg, resp)
tweepy.error.TweepError: Twitter error response: status code = 403
[2015/07/31 09:01:49]CRITICAL - horesase_bot.py:138: user_timeline fetch error
Traceback (most recent call last):
  File "horesase_bot.py", line 136, in get_user_text
    user_tweets = api.user_timeline(id=user, count=20)
  File "/usr/local/lib/python3.4/site-packages/tweepy/binder.py", line 239, in _call
    return method.execute()
  File "/usr/local/lib/python3.4/site-packages/tweepy/binder.py", line 223, in execute
    raise TweepError(error_msg, resp)
tweepy.error.TweepError: Twitter error response: status code = 401
[2015/07/31 13:01:19]CRITICAL - horesase_bot.py:138: user_timeline fetch error
Traceback (most recent call last):
  File "horesase_bot.py", line 136, in get_user_text
    user_tweets = api.user_timeline(id=user, count=20)
  File "/usr/local/lib/python3.4/site-packages/tweepy/binder.py", line 239, in _call
    return method.execute()
  File "/usr/local/lib/python3.4/site-packages/tweepy/binder.py", line 223, in execute
    raise TweepError(error_msg, resp)
tweepy.error.TweepError: Twitter error response: status code = 401
[2015/07/31 13:01:55]ERROR - horesase_bot.py:278: reply error
Traceback (most recent call last):
  File "horesase_bot.py", line 275, in main
    api.update_with_media('data/picture.gif', reply_text, in_reply_to_status_id=user_tweet.id)
  File "/usr/local/lib/python3.4/site-packages/tweepy/api.py", line 231, in update_with_media
    )(*args, **kwargs)
  File "/usr/local/lib/python3.4/site-packages/tweepy/binder.py", line 239, in _call
    return method.execute()
  File "/usr/local/lib/python3.4/site-packages/tweepy/binder.py", line 223, in execute
    raise TweepError(error_msg, resp)
tweepy.error.TweepError: Twitter error response: status code = 403
[2015/07/31 23:02:04]ERROR - horesase_bot.py:278: reply error
Traceback (most recent call last):
  File "horesase_bot.py", line 275, in main
    api.update_with_media('data/picture.gif', reply_text, in_reply_to_status_id=user_tweet.id)
  File "/usr/local/lib/python3.4/site-packages/tweepy/api.py", line 231, in update_with_media
    )(*args, **kwargs)
  File "/usr/local/lib/python3.4/site-packages/tweepy/binder.py", line 239, in _call
    return method.execute()
  File "/usr/local/lib/python3.4/site-packages/tweepy/binder.py", line 223, in execute
    raise TweepError(error_msg, resp)
tweepy.error.TweepError: Twitter error response: status code = 403
[2015/07/31 23:02:09]CRITICAL - horesase_bot.py:138: user_timeline fetch error
Traceback (most recent call last):
  File "horesase_bot.py", line 136, in get_user_text
    user_tweets = api.user_timeline(id=user, count=20)
  File "/usr/local/lib/python3.4/site-packages/tweepy/binder.py", line 239, in _call
    return method.execute()
  File "/usr/local/lib/python3.4/site-packages/tweepy/binder.py", line 223, in execute
    raise TweepError(error_msg, resp)
tweepy.error.TweepError: Twitter error response: status code = 401
[2015/07/31 23:02:11]ERROR - horesase_bot.py:278: reply error
Traceback (most recent call last):
  File "horesase_bot.py", line 275, in main
    api.update_with_media('data/picture.gif', reply_text, in_reply_to_status_id=user_tweet.id)
  File "/usr/local/lib/python3.4/site-packages/tweepy/api.py", line 231, in update_with_media
    )(*args, **kwargs)
  File "/usr/local/lib/python3.4/site-packages/tweepy/binder.py", line 239, in _call
    return method.execute()
  File "/usr/local/lib/python3.4/site-packages/tweepy/binder.py", line 223, in execute
    raise TweepError(error_msg, resp)
tweepy.error.TweepError: Twitter error response: status code = 403
[2015/08/01 03:01:35]CRITICAL - horesase_bot.py:138: user_timeline fetch error
Traceback (most recent call last):
  File "horesase_bot.py", line 136, in get_user_text
    user_tweets = api.user_timeline(id=user, count=20)
  File "/usr/local/lib/python3.4/site-packages/tweepy/binder.py", line 239, in _call
    return method.execute()
  File "/usr/local/lib/python3.4/site-packages/tweepy/binder.py", line 223, in execute
    raise TweepError(error_msg, resp)
tweepy.error.TweepError: Twitter error response: status code = 401
[2015/08/01 03:43:19]ERROR - horesase_bot.py:283: reply error
Traceback (most recent call last):
  File "horesase_bot.py", line 280, in main
    api.update_with_media('data/picture.gif', reply_text, in_reply_to_status_id=user_tweet.id)
  File "/usr/local/lib/python3.4/site-packages/tweepy/api.py", line 231, in update_with_media
    )(*args, **kwargs)
  File "/usr/local/lib/python3.4/site-packages/tweepy/binder.py", line 239, in _call
    return method.execute()
  File "/usr/local/lib/python3.4/site-packages/tweepy/binder.py", line 223, in execute
    raise TweepError(error_msg, resp)
tweepy.error.TweepError: Twitter error response: status code = 403
[2015/08/01 03:43:23]ERROR - horesase_bot.py:283: reply error
Traceback (most recent call last):
  File "horesase_bot.py", line 280, in main
    api.update_with_media('data/picture.gif', reply_text, in_reply_to_status_id=user_tweet.id)
  File "/usr/local/lib/python3.4/site-packages/tweepy/api.py", line 231, in update_with_media
    )(*args, **kwargs)
  File "/usr/local/lib/python3.4/site-packages/tweepy/binder.py", line 239, in _call
    return method.execute()
  File "/usr/local/lib/python3.4/site-packages/tweepy/binder.py", line 223, in execute
    raise TweepError(error_msg, resp)
tweepy.error.TweepError: Twitter error response: status code = 403
[2015/08/01 03:43:26]ERROR - horesase_bot.py:283: reply error
Traceback (most recent call last):
  File "horesase_bot.py", line 280, in main
    api.update_with_media('data/picture.gif', reply_text, in_reply_to_status_id=user_tweet.id)
  File "/usr/local/lib/python3.4/site-packages/tweepy/api.py", line 231, in update_with_media
    )(*args, **kwargs)
  File "/usr/local/lib/python3.4/site-packages/tweepy/binder.py", line 239, in _call
    return method.execute()
  File "/usr/local/lib/python3.4/site-packages/tweepy/binder.py", line 223, in execute
    raise TweepError(error_msg, resp)
tweepy.error.TweepError: Twitter error response: status code = 403
[2015/08/01 03:43:49]CRITICAL - horesase_bot.py:139: user_timeline fetch error
Traceback (most recent call last):
  File "horesase_bot.py", line 137, in get_user_text
    user_tweets = api.user_timeline(id=user, count=20)
  File "/usr/local/lib/python3.4/site-packages/tweepy/binder.py", line 239, in _call
    return method.execute()
  File "/usr/local/lib/python3.4/site-packages/tweepy/binder.py", line 223, in execute
    raise TweepError(error_msg, resp)
tweepy.error.TweepError: Twitter error response: status code = 401
[2015/08/01 09:00:50]CRITICAL - horesase_bot.py:139: user_timeline fetch error
Traceback (most recent call last):
  File "horesase_bot.py", line 137, in get_user_text
    user_tweets = api.user_timeline(id=user, count=20)
  File "/usr/local/lib/python3.4/site-packages/tweepy/binder.py", line 239, in _call
    return method.execute()
  File "/usr/local/lib/python3.4/site-packages/tweepy/binder.py", line 223, in execute
    raise TweepError(error_msg, resp)
tweepy.error.TweepError: Twitter error response: status code = 401
[2015/08/01 09:01:32]ERROR - horesase_bot.py:283: reply error
Traceback (most recent call last):
  File "horesase_bot.py", line 280, in main
    api.update_with_media('data/picture.gif', reply_text, in_reply_to_status_id=user_tweet.id)
  File "/usr/local/lib/python3.4/site-packages/tweepy/api.py", line 231, in update_with_media
    )(*args, **kwargs)
  File "/usr/local/lib/python3.4/site-packages/tweepy/binder.py", line 239, in _call
    return method.execute()
  File "/usr/local/lib/python3.4/site-packages/tweepy/binder.py", line 223, in execute
    raise TweepError(error_msg, resp)
tweepy.error.TweepError: Twitter error response: status code = 403
[2015/08/01 09:01:38]ERROR - horesase_bot.py:283: reply error
Traceback (most recent call last):
  File "horesase_bot.py", line 280, in main
    api.update_with_media('data/picture.gif', reply_text, in_reply_to_status_id=user_tweet.id)
  File "/usr/local/lib/python3.4/site-packages/tweepy/api.py", line 231, in update_with_media
    )(*args, **kwargs)
  File "/usr/local/lib/python3.4/site-packages/tweepy/binder.py", line 239, in _call
    return method.execute()
  File "/usr/local/lib/python3.4/site-packages/tweepy/binder.py", line 223, in execute
    raise TweepError(error_msg, resp)
tweepy.error.TweepError: Twitter error response: status code = 403
[2015/08/01 13:05:15]CRITICAL - horesase_bot.py:139: user_timeline fetch error
Traceback (most recent call last):
  File "horesase_bot.py", line 137, in get_user_text
    user_tweets = api.user_timeline(id=user, count=20)
  File "/usr/local/lib/python3.4/site-packages/tweepy/binder.py", line 239, in _call
    return method.execute()
  File "/usr/local/lib/python3.4/site-packages/tweepy/binder.py", line 223, in execute
    raise TweepError(error_msg, resp)
tweepy.error.TweepError: Twitter error response: status code = 401
[2015/08/01 13:05:23]ERROR - horesase_bot.py:284: reply error
Traceback (most recent call last):
  File "horesase_bot.py", line 281, in main
    api.update_with_media('data/picture.gif', reply_text, in_reply_to_status_id=user_tweet.id)
  File "/usr/local/lib/python3.4/site-packages/tweepy/api.py", line 231, in update_with_media
    )(*args, **kwargs)
  File "/usr/local/lib/python3.4/site-packages/tweepy/binder.py", line 239, in _call
    return method.execute()
  File "/usr/local/lib/python3.4/site-packages/tweepy/binder.py", line 223, in execute
    raise TweepError(error_msg, resp)
tweepy.error.TweepError: Twitter error response: status code = 403
[2015/08/01 13:06:15]ERROR - horesase_bot.py:284: reply error
Traceback (most recent call last):
  File "horesase_bot.py", line 281, in main
    api.update_with_media('data/picture.gif', reply_text, in_reply_to_status_id=user_tweet.id)
  File "/usr/local/lib/python3.4/site-packages/tweepy/api.py", line 231, in update_with_media
    )(*args, **kwargs)
  File "/usr/local/lib/python3.4/site-packages/tweepy/binder.py", line 239, in _call
    return method.execute()
  File "/usr/local/lib/python3.4/site-packages/tweepy/binder.py", line 223, in execute
    raise TweepError(error_msg, resp)
tweepy.error.TweepError: Twitter error response: status code = 403
[2015/08/01 15:28:44]CRITICAL - horesase_bot.py:140: user_timeline fetch error
Traceback (most recent call last):
  File "horesase_bot.py", line 138, in get_user_text
    user_tweets = api.user_timeline(id=user, count=20)
  File "/usr/local/lib/python3.4/site-packages/tweepy/binder.py", line 239, in _call
    return method.execute()
  File "/usr/local/lib/python3.4/site-packages/tweepy/binder.py", line 223, in execute
    raise TweepError(error_msg, resp)
tweepy.error.TweepError: Twitter error response: status code = 401
[2015/08/01 15:32:09]CRITICAL - horesase_bot.py:140: user_timeline fetch error
Traceback (most recent call last):
  File "horesase_bot.py", line 138, in get_user_text
    user_tweets = api.user_timeline(id=user, count=20)
  File "/usr/local/lib/python3.4/site-packages/tweepy/binder.py", line 239, in _call
    return method.execute()
  File "/usr/local/lib/python3.4/site-packages/tweepy/binder.py", line 223, in execute
    raise TweepError(error_msg, resp)
tweepy.error.TweepError: Twitter error response: status code = 401
[2015/08/01 15:33:36]CRITICAL - horesase_bot.py:140: user_timeline fetch error
Traceback (most recent call last):
  File "horesase_bot.py", line 138, in get_user_text
    user_tweets = api.user_timeline(id=user, count=20)
  File "/usr/local/lib/python3.4/site-packages/tweepy/binder.py", line 239, in _call
    return method.execute()
  File "/usr/local/lib/python3.4/site-packages/tweepy/binder.py", line 223, in execute
    raise TweepError(error_msg, resp)
tweepy.error.TweepError: Twitter error response: status code = 401
[2015/08/01 15:37:27]CRITICAL - horesase_bot.py:140: user_timeline fetch error
Traceback (most recent call last):
  File "horesase_bot.py", line 138, in get_user_text
    user_tweets = api.user_timeline(id=user, count=20)
  File "/usr/local/lib/python3.4/site-packages/tweepy/binder.py", line 239, in _call
    return method.execute()
  File "/usr/local/lib/python3.4/site-packages/tweepy/binder.py", line 223, in execute
    raise TweepError(error_msg, resp)
tweepy.error.TweepError: Twitter error response: status code = 401
[2015/08/01 15:45:06]CRITICAL - horesase_bot.py:140: user_timeline fetch error
Traceback (most recent call last):
  File "horesase_bot.py", line 138, in get_user_text
    user_tweets = api.user_timeline(id=user, count=20)
  File "/usr/local/lib/python3.4/site-packages/tweepy/binder.py", line 239, in _call
    return method.execute()
  File "/usr/local/lib/python3.4/site-packages/tweepy/binder.py", line 223, in execute
    raise TweepError(error_msg, resp)
tweepy.error.TweepError: Twitter error response: status code = 401
[2015/08/01 16:06:45]CRITICAL - horesase_bot.py:140: user_timeline fetch error
Traceback (most recent call last):
  File "horesase_bot.py", line 138, in get_user_text
    user_tweets = api.user_timeline(id=user, count=20)
  File "/usr/local/lib/python3.4/site-packages/tweepy/binder.py", line 239, in _call
    return method.execute()
  File "/usr/local/lib/python3.4/site-packages/tweepy/binder.py", line 223, in execute
    raise TweepError(error_msg, resp)
tweepy.error.TweepError: Twitter error response: status code = 401
[2015/08/01 16:11:32]CRITICAL - horesase_bot.py:140: user_timeline fetch error
Traceback (most recent call last):
  File "horesase_bot.py", line 138, in get_user_text
    user_tweets = api.user_timeline(id=user, count=20)
  File "/usr/local/lib/python3.4/site-packages/tweepy/binder.py", line 239, in _call
    return method.execute()
  File "/usr/local/lib/python3.4/site-packages/tweepy/binder.py", line 223, in execute
    raise TweepError(error_msg, resp)
tweepy.error.TweepError: Twitter error response: status code = 401
[2015/08/01 16:17:38]CRITICAL - horesase_bot.py:140: user_timeline fetch error
Traceback (most recent call last):
  File "horesase_bot.py", line 138, in get_user_text
    user_tweets = api.user_timeline(id=user, count=20)
  File "/usr/local/lib/python3.4/site-packages/tweepy/binder.py", line 239, in _call
    return method.execute()
  File "/usr/local/lib/python3.4/site-packages/tweepy/binder.py", line 223, in execute
    raise TweepError(error_msg, resp)
tweepy.error.TweepError: Twitter error response: status code = 401
[2015/08/01 16:19:47]CRITICAL - horesase_bot.py:140: user_timeline fetch error
Traceback (most recent call last):
  File "horesase_bot.py", line 138, in get_user_text
    user_tweets = api.user_timeline(id=user, count=20)
  File "/usr/local/lib/python3.4/site-packages/tweepy/binder.py", line 239, in _call
    return method.execute()
  File "/usr/local/lib/python3.4/site-packages/tweepy/binder.py", line 223, in execute
    raise TweepError(error_msg, resp)
tweepy.error.TweepError: Twitter error response: status code = 401
[2015/08/01 16:51:54]CRITICAL - horesase_bot.py:140: user_timeline fetch error
Traceback (most recent call last):
  File "horesase_bot.py", line 138, in get_user_text
    user_tweets = api.user_timeline(id=user, count=20)
  File "/usr/local/lib/python3.4/site-packages/tweepy/binder.py", line 239, in _call
    return method.execute()
  File "/usr/local/lib/python3.4/site-packages/tweepy/binder.py", line 223, in execute
    raise TweepError(error_msg, resp)
tweepy.error.TweepError: Twitter error response: status code = 401
[2015/08/01 16:57:35]CRITICAL - horesase_bot.py:140: user_timeline fetch error
Traceback (most recent call last):
  File "horesase_bot.py", line 138, in get_user_text
    user_tweets = api.user_timeline(id=user, count=20)
  File "/usr/local/lib/python3.4/site-packages/tweepy/binder.py", line 239, in _call
    return method.execute()
  File "/usr/local/lib/python3.4/site-packages/tweepy/binder.py", line 223, in execute
    raise TweepError(error_msg, resp)
tweepy.error.TweepError: Twitter error response: status code = 401
